Workbook
Name data: Data!$A:$Z
Name HoaDon: #REF!
Name KSHT: KhaoSatHienTruong!$A:$Z
Name NhanSu: NhanSu!$D:$I
Name tab: REPT(" ",10)

Sheet Data
A1: =ROW() -> 1 | B1: CongTrinh | C1: NoiDungCongTac | D1: BatDau | E1: KetThuc | F1: DiaDiem | G1: KhoiLuong | H1: VatTu | I1: DungCuAnToan | J1: DuCuDoLuong | K1: DungCuThiCong | L1: ThietBiDongCat | M1: ViTriTiepDia | N1: BienBao | O1: PhuongThucTruyenLenh | P1: PhamVi | Q1: GiayBanGiao | R1: Đơn vị 1 | S1: Đơn vị 2 | T1: Đơn vị 3 | U1: Đơn vị 4 | V1: BanGiao1 | W1: BanGiao2 | X1: BanGiao3 | Y1: DOTinCay
A3: =ROW() -> 3 | E3: =D3 -> 0 | K3: Xe cẩu 5T: 02 xe. Kích tăng dây: 4 cái. Kìm ép thủy lực: 3 cái. Puly: 6 cái. Các dụng cụ khác như cle, mỏ lết, cuốc, xà beng … | L3: FCO và MCCB TBA Minh Khai 1 | M3: Tại TBA Minh Khai 1 | N3: Đã tiếp địa, Cấm đóng điện | O3: Trực tiếp | P3: {="Đơn vị công tác 1: Thực hiện công tác theo PCT/LCT............. Nội dung công việc: thực hiện trong phạm vi "&_xlfn.TEXTJOIN(CHAR(10),TRUE,R3:U3)} -> Đơn vị công tác 1: Thực hiện công tác theo PCT/LCT............. Nội dung công việc: thực hiện trong phạm vi từ trụ 03/01 đến trụ 03/11 | Q3: {=_xlfn.TEXTJOIN(CHAR(10),TRUE,V3:X3)} -> Không | R3: từ trụ 03/01 đến trụ 03/11 | V3: Không | Y3: 1. MAIFI: 0 2. SAIDI: 0,9 3. SAIFI: 0,001
A4: =ROW() -> 4 | B4: Di dời hệ thống điện trung hạ thế, trạm biến áp - thuộc dự án: Đường Nguyễn Thị Minh Khai, Huyện Xuân Lộc | C4: Di dời lưới hạ thế ABC độc lập | D4: 44073 | E4: =D4 -> 44073 | F4: Lưới hạ thế độc lập sau TBA Minh Khai 1 | G4: Di dời 11 trụ hạ thế từ trụ 03/01 đến trụ 03/11 và toàn bộ dây khách hàng đấu nối vào lưới hạ thế hiện hữu | H4: Sử dụng lại toàn bộ vật tư hiện hữu | I4: Dây đai an toàn, quần, áo, nón bảo hộ lao động… Găng tay hạ thế | J4: Amper kìm, máy đo điện trở tiếp địa… | K4: Xe cẩu 5T: 02 xe. Kích tăng dây: 4 cái. Kìm ép thủy lực: 3 cái. Puly: 6 cái. Các dụng cụ khác như cle, mỏ lết, cuốc, xà beng … | L4: FCO và MCCB TBA Minh Khai 1 | M4: Tại TBA Minh Khai 1 | N4: Đã tiếp địa, Cấm đóng điện | O4: Trực tiếp | P4: {="Đơn vị công tác 1: Thực hiện công tác theo PCT/LCT............. Nội dung công việc: thực hiện trong phạm vi "&_xlfn.TEXTJOIN(CHAR(10),TRUE,R4:U4)} -> Đơn vị công tác 1: Thực hiện công tác theo PCT/LCT............. Nội dung công việc: thực hiện trong phạm vi từ trụ 03/01 đến trụ 03/11 | Q4: {=_xlfn.TEXTJOIN(CHAR(10),TRUE,V4:X4)} -> Không | R4: từ trụ 03/01 đến trụ 03/11 | V4: Không | Y4: 1. MAIFI: 0 2. SAIDI: 0,9 3. SAIFI: 0,001
A5: =ROW() -> 5 | B5: Di dời hệ thống điện trung hạ thế, trạm biến áp - thuộc dự án: Đường Xuân Bắc - Bảo Quang | C5: Di dời hệ thống điện trung hạ thế | D5: 44077 | E5: =D5 -> 44077 | F5: Hệ thống điện trung hạ thế thuộc nhánh rẽ Thọ Vực | G5: a. Đường dây trung thế: Phương án di dời: Thực hiện di dời lưới điện trung thế hiện hữu ra phía ngoài chỉ giới xây dựng, cách tìm đường hiện hữu 7-8m: Di dời trụ 09 trụ: 001A; 024; 030; 030A; 031; 031A; 032; 046A; 054A. + Trụ TT001A: Sử dụng trụ, đà, sứ hiện hữu. Thay dây cột sứ hiện hữu. + Trụ TT024: Sử dụng trụ, đà, sứ hiện hữu. Thay dây cột sứ hiện hữu. + Trụ TT030: Sử dụng trụ, đà, sứ hiện hữu. Thay dây cột sứ hiện hữu. + Trụ TT030A: Sử dụng trụ, đà, sứ hiện hữu. Thay dây cột sứ hiện hữu. + Trụ TT031: Sử dụng trụ, đà, sứ hiện hữu. + Trụ TT032: Sử dụng trụ, đà, sứ hiện hữu. + Trụ TT046A: Sử dụng trụ, đà, sứ hiện hữu. + Trụ TT054A: Sử dụng trụ, đà, sứ hiện hữu. + Khoảng trụ 054A đến 054A/001: Thay dây dẫn trung thế từ 3AC50 + AC50 thành 3ACXH50 + AC50mm. Thu hồi 240m cáp AC50mm. b. Đường dây hạ thế sau TBA Xuân Bắc 6A, 6C, Thọ Vực 3: - Cấp điện áp 220/380V - Dây dẫn hiện hữu: 2AV70 + A50; ABC3x95mm2. - Phương án di dời: Thực hiện di dời lưới điện hạ thế hiên hữu ra phia ngoài chi giới dựng, cách tim đường hiện hữu 7-8m: 9 trụ. Sử dụng lại vật tư hiện hữu. + Khoảng trụ 054A đến 054A/HT01: Thay dây dẫn hạ thế từ 3AV70 + A50 thành ABC4x95mm. Thu hồi 120m cáp AV70mm, 40m cáp A50. c. Trạm biến áp Di dời 01 TBA treo trên trụ trung thế hiện hữu ra phía ngoài chi giới xây dựng, cách tim đường hiện hữu 8m: Di dời TBA Thọ Vực 3. | H5: Sử dụng lại toàn bộ vật tư hiện hữu | I5: Dây đai an toàn, quần, áo, nón bảo hộ lao động… Găng tay hạ thế | J5: Máy đo điện trở tiếp địa, điện trở tiếp xúc. | K5: Xe cẩu 5T: 02 xe. Kích tăng dây: 4 cái. Kìm ép thủy lực: 3 cái. Puly: 6 cái. Các dụng cụ khác như cle, mỏ lết, cuốc, xà beng … | L5: Cắt Recloser Thọ Vực + 3LTD nhánh rẽ Thọ Vực | M5: Tại trụ 001A nhánh rẽ Thọ Vực | N5: Đã tiếp địa, Cấm đóng điện | O5: Trực tiếp | P5: {=_xlfn.TEXTJOIN(CHAR(10),TRUE,R5:U5)} -> từ trụ 001A đến trụ 012 lưới hạ thế trạm Xuân Bắc 6A, 6C thuộc nhánh rẽ Thọ Vực từ trụ 001A đến trụ 054 thuộc nhánh rẽ Thọ Vực từ trụ 054 đến trụ 055 và trụ 054/001 thuộc nhánh rẽ Thọ Vực | Q5: {=_xlfn.TEXTJOIN(CHAR(10),TRUE,V5:X5)} -> Không | R5: từ trụ 001A đến trụ 012 lưới hạ thế trạm Xuân Bắc 6A, 6C thuộc nhánh rẽ Thọ Vực | S5: từ trụ 001A đến trụ 054 thuộc nhánh rẽ Thọ Vực | T5: từ trụ 054 đến trụ 055 và trụ 054/001 thuộc nhánh rẽ Thọ Vực | V5: Không | Y5: 1. MAIFI: 0 2. SAIDI: 11,5 3. SAIFI: 0,02
A6: =ROW() -> 6 | B6: Cải tạo lưới điện trung hạ thế huyện Cẩm Mỹ năm 2020 | C6: Thay dây hạ thế TBA Nam Hà 1 | D6: 44079 | E6: =D6 -> 44079 | F6: Đường dây hạ thế sau TBA Nam hà 1
A7: =ROW() -> 7 | B7: Cải tạo lưới điện trung hạ thế huyện Cẩm Mỹ năm 2020 | C7: Thay dây hạ thế TBA Nam Hà 1A | D7: 44080 | E7: =D7 -> 44080
A8: =ROW() -> 8 | B8: Cải tạo lưới điện trung hạ thế huyện Cẩm Mỹ năm 2020 | C8: Thay dây hạ thế TBA Nam Hà 3 | D8: 44081 | E8: =D8 -> 44081
A9: =ROW() -> 9 | B9: Cải tạo lưới điện trung hạ thế huyện Cẩm Mỹ năm 2020 | C9: Thay dây hạ thế TBA Xuân Tây 10A | D9: 44083 | E9: =D9 -> 44083

Sheet Merge
A1: =ROW() -> 1 | B1: =VLOOKUP(ROW(),data,COLUMN(),0) -> CongTrinh | C1: =VLOOKUP(ROW(),data,COLUMN(),0) -> NoiDungCongTac | D1: =VLOOKUP(ROW(),data,COLUMN(),0) -> BatDau | E1: =VLOOKUP(ROW(),data,COLUMN(),0) -> KetThuc | F1: =VLOOKUP(ROW(),data,COLUMN(),0) -> DiaDiem | G1: =VLOOKUP(ROW(),data,COLUMN(),0) -> KhoiLuong | H1: =VLOOKUP(ROW(),data,COLUMN(),0) -> VatTu | I1: =VLOOKUP(ROW(),data,COLUMN(),0) -> DungCuAnToan | ... X1: =VLOOKUP(ROW(),data,COLUMN(),0) -> BanGiao3
B2: ab ab ab ab ab ab ab ab ab ab ab ab ab ab ab ab ab ab ab ab ab ab ab ab ab ab ab ab ab ab ab ab ab ab ab ab ab ab ab ab ab ab ab ab ab ab ab ab ab ab ab ab ab ab ab ab ab ab ab ab ab ab ab ab ab ab ab ab ab ab ab ab ab ab ab ab ab ab ab ab ab ab ab ab ab ab ab ab ab ab ab ab ab ab ab ab ab ab ab ab ab ab ab ab ab ab ab ab ab ab ab ab ab ab ab ab ab ab ab ab ab ab ab ab ab ab ab ab ab ab ab ab ab ab ab ab ab ab ab ab ab ab ab ab ab ab ab ab ab ab ab ab ab ab ab ab ab ab ab ab ab ab ab ab ab ab ab ab ab ab ab ab ab ab ab ab ab ab ab ab ab ab ab ab ab ab ab ab ab ab ab ab ab ab ab ab ab ab ab ab ab ab ab ab ab ab ab ab ab ab ab ab ab ab ab ab ab ab ab ab ab ab ab ab ab ab ab ab ab ab ab ab ab ab ab ab ab ab ab ab ab ab ab ab ab ab ab ab ab ab ab ab ab ab ab | C2: ab ab ab ab ab ab ab ab ab ab ab ab ab ab ab ab ab ab ab ab ab ab ab ab ab ab ab ab ab ab ab ab ab ab ab ab ab ab ab ab ab ab ab ab ab ab ab ab ab ab ab ab ab ab ab ab ab ab ab ab ab ab ab ab ab ab ab ab ab ab ab ab ab ab ab ab ab ab ab ab ab ab ab ab ab ab ab ab ab ab ab ab ab ab ab ab ab ab ab ab ab ab ab ab ab ab ab ab ab ab ab ab ab ab ab ab ab ab ab ab ab ab ab ab ab ab ab ab ab ab ab ab ab ab ab ab ab ab ab ab ab ab ab ab ab ab ab ab ab ab ab ab ab ab ab ab ab ab ab ab ab ab ab ab ab ab ab ab ab ab ab ab ab ab ab ab ab ab ab ab ab ab ab ab ab ab ab ab ab ab ab ab ab ab ab ab ab ab ab ab ab ab ab ab ab ab ab ab ab ab ab ab ab ab ab ab ab ab ab ab ab ab ab ab ab ab ab ab ab ab ab ab ab ab ab ab ab ab ab ab ab ab ab ab ab ab ab ab ab ab ab ab ab ab ab | D2: ab ab ab ab ab ab ab ab ab ab ab ab ab ab ab ab ab ab ab ab ab ab ab ab ab ab ab ab ab ab ab ab ab ab ab ab ab ab ab ab ab ab ab ab ab ab ab ab ab ab ab ab ab ab ab ab ab ab ab ab ab ab ab ab ab ab ab ab ab ab ab ab ab ab ab ab ab ab ab ab ab ab ab ab ab ab ab ab ab ab ab ab ab ab ab ab ab ab ab ab ab ab ab ab ab ab ab ab ab ab ab ab ab ab ab ab ab ab ab ab ab ab ab ab ab ab ab ab ab ab ab ab ab ab ab ab ab ab ab ab ab ab ab ab ab ab ab ab ab ab ab ab ab ab ab ab ab ab ab ab ab ab ab ab ab ab ab ab ab ab ab ab ab ab ab ab ab ab ab ab ab ab ab ab ab ab ab ab ab ab ab ab ab ab ab ab ab ab ab ab ab ab ab ab ab ab ab ab ab ab ab ab ab ab ab ab ab ab ab ab ab ab ab ab ab ab ab ab ab ab ab ab ab ab ab ab ab ab ab ab ab ab ab ab ab ab ab ab ab ab ab ab ab ab ab | E2: ab ab ab ab ab ab ab ab ab ab ab ab ab ab ab ab ab ab ab ab ab ab ab ab ab ab ab ab ab ab ab ab ab ab ab ab ab ab ab ab ab ab ab ab ab ab ab ab ab ab ab ab ab ab ab ab ab ab ab ab ab ab ab ab ab ab ab ab ab ab ab ab ab ab ab ab ab ab ab ab ab ab ab ab ab ab ab ab ab ab ab ab ab ab ab ab ab ab ab ab ab ab ab ab ab ab ab ab ab ab ab ab ab ab ab ab ab ab ab ab ab ab ab ab ab ab ab ab ab ab ab ab ab ab ab ab ab ab ab ab ab ab ab ab ab ab ab ab ab ab ab ab ab ab ab ab ab ab ab ab ab ab ab ab ab ab ab ab ab ab ab ab ab ab ab ab ab ab ab ab ab ab ab ab ab ab ab ab ab ab ab ab ab ab ab ab ab ab ab ab ab ab ab ab ab ab ab ab ab ab ab ab ab ab ab ab ab ab ab ab ab ab ab ab ab ab ab ab ab ab ab ab ab ab ab ab ab ab ab ab ab ab ab ab ab ab ab ab ab ab ab ab ab ab ab | F2: ab ab ab ab ab ab ab ab ab ab ab ab ab ab ab ab ab ab ab ab ab ab ab ab ab ab ab ab ab ab ab ab ab ab ab ab ab ab ab ab ab ab ab ab ab ab ab ab ab ab ab ab ab ab ab ab ab ab ab ab ab ab ab ab ab ab ab ab ab ab ab ab ab ab ab ab ab ab ab ab ab ab ab ab ab ab ab ab ab ab ab ab ab ab ab ab ab ab ab ab ab ab ab ab ab ab ab ab ab ab ab ab ab ab ab ab ab ab ab ab ab ab ab ab ab ab ab ab ab ab ab ab ab ab ab ab ab ab ab ab ab ab ab ab ab ab ab ab ab ab ab ab ab ab ab ab ab ab ab ab ab ab ab ab ab ab ab ab ab ab ab ab ab ab ab ab ab ab ab ab ab ab ab ab ab ab ab ab ab ab ab ab ab ab ab ab ab ab ab ab ab ab ab ab ab ab ab ab ab ab ab ab ab ab ab ab ab ab ab ab ab ab ab ab ab ab ab ab ab ab ab ab ab ab ab ab ab ab ab ab ab ab ab ab ab ab ab ab ab ab ab ab ab ab ab | G2: ab ab ab ab ab ab ab ab ab ab ab ab ab ab ab ab ab ab ab ab ab ab ab ab ab ab ab ab ab ab ab ab ab ab ab ab ab ab ab ab ab ab ab ab ab ab ab ab ab ab ab ab ab ab ab ab ab ab ab ab ab ab ab ab ab ab ab ab ab ab ab ab ab ab ab ab ab ab ab ab ab ab ab ab ab ab ab ab ab ab ab ab ab ab ab ab ab ab ab ab ab ab ab ab ab ab ab ab ab ab ab ab ab ab ab ab ab ab ab ab ab ab ab ab ab ab ab ab ab ab ab ab ab ab ab ab ab ab ab ab ab ab ab ab ab ab ab ab ab ab ab ab ab ab ab ab ab ab ab ab ab ab ab ab ab ab ab ab ab ab ab ab ab ab ab ab ab ab ab ab ab ab ab ab ab ab ab ab ab ab ab ab ab ab ab ab ab ab ab ab ab ab ab ab ab ab ab ab ab ab ab ab ab ab ab ab ab ab ab ab ab ab ab ab ab ab ab ab ab ab ab ab ab ab ab ab ab ab ab ab ab ab ab ab ab ab ab ab ab ab ab ab ab ab ab | H2: ab ab ab ab ab ab ab ab ab ab ab ab ab ab ab ab ab ab ab ab ab ab ab ab ab ab ab ab ab ab ab ab ab ab ab ab ab ab ab ab ab ab ab ab ab ab ab ab ab ab ab ab ab ab ab ab ab ab ab ab ab ab ab ab ab ab ab ab ab ab ab ab ab ab ab ab ab ab ab ab ab ab ab ab ab ab ab ab ab ab ab ab ab ab ab ab ab ab ab ab ab ab ab ab ab ab ab ab ab ab ab ab ab ab ab ab ab ab ab ab ab ab ab ab ab ab ab ab ab ab ab ab ab ab ab ab ab ab ab ab ab ab ab ab ab ab ab ab ab ab ab ab ab ab ab ab ab ab ab ab ab ab ab ab ab ab ab ab ab ab ab ab ab ab ab ab ab ab ab ab ab ab ab ab ab ab ab ab ab ab ab ab ab ab ab ab ab ab ab ab ab ab ab ab ab ab ab ab ab ab ab ab ab ab ab ab ab ab ab ab ab ab ab ab ab ab ab ab ab ab ab ab ab ab ab ab ab ab ab ab ab ab ab ab ab ab ab ab ab ab ab ab ab ab ab | I2: ab ab ab ab ab ab ab ab ab ab ab ab ab ab ab ab ab ab ab ab ab ab ab ab ab ab ab ab ab ab ab ab ab ab ab ab ab ab ab ab ab ab ab ab ab ab ab ab ab ab ab ab ab ab ab ab ab ab ab ab ab ab ab ab ab ab ab ab ab ab ab ab ab ab ab ab ab ab ab ab ab ab ab ab ab ab ab ab ab ab ab ab ab ab ab ab ab ab ab ab ab ab ab ab ab ab ab ab ab ab ab ab ab ab ab ab ab ab ab ab ab ab ab ab ab ab ab ab ab ab ab ab ab ab ab ab ab ab ab ab ab ab ab ab ab ab ab ab ab ab ab ab ab ab ab ab ab ab ab ab ab ab ab ab ab ab ab ab ab ab ab ab ab ab ab ab ab ab ab ab ab ab ab ab ab ab ab ab ab ab ab ab ab ab ab ab ab ab ab ab ab ab ab ab ab ab ab ab ab ab ab ab ab ab ab ab ab ab ab ab ab ab ab ab ab ab ab ab ab ab ab ab ab ab ab ab ab ab ab ab ab ab ab ab ab ab ab ab ab ab ab ab ab ab ab | J2: ab ab ab ab ab ab ab ab ab ab ab ab ab ab ab ab ab ab ab ab ab ab ab ab ab ab ab ab ab ab ab ab ab ab ab ab ab ab ab ab ab ab ab ab ab ab ab ab ab ab ab ab ab ab ab ab ab ab ab ab ab ab ab ab ab ab ab ab ab ab ab ab ab ab ab ab ab ab ab ab ab ab ab ab ab ab ab ab ab ab ab ab ab ab ab ab ab ab ab ab ab ab ab ab ab ab ab ab ab ab ab ab ab ab ab ab ab ab ab ab ab ab ab ab ab ab ab ab ab ab ab ab ab ab ab ab ab ab ab ab ab ab ab ab ab ab ab ab ab ab ab ab ab ab ab ab ab ab ab ab ab ab ab ab ab ab ab ab ab ab ab ab ab ab ab ab ab ab ab ab ab ab ab ab ab ab ab ab ab ab ab ab ab ab ab ab ab ab ab ab ab ab ab ab ab ab ab ab ab ab ab ab ab ab ab ab ab ab ab ab ab ab ab ab ab ab ab ab ab ab ab ab ab ab ab ab ab ab ab ab ab ab ab ab ab ab ab ab ab ab ab ab ab ab ab | K2: ab ab ab ab ab ab ab ab ab ab ab ab ab ab ab ab ab ab ab ab ab ab ab ab ab ab ab ab ab ab ab ab ab ab ab ab ab ab ab ab ab ab ab ab ab ab ab ab ab ab ab ab ab ab ab ab ab ab ab ab ab ab ab ab ab ab ab ab ab ab ab ab ab ab ab ab ab ab ab ab ab ab ab ab ab ab ab ab ab ab ab ab ab ab ab ab ab ab ab ab ab ab ab ab ab ab ab ab ab ab ab ab ab ab ab ab ab ab ab ab ab ab ab ab ab ab ab ab ab ab ab ab ab ab ab ab ab ab ab ab ab ab ab ab ab ab ab ab ab ab ab ab ab ab ab ab ab ab ab ab ab ab ab ab ab ab ab ab ab ab ab ab ab ab ab ab ab ab ab ab ab ab ab ab ab ab ab ab ab ab ab ab ab ab ab ab ab ab ab ab ab ab ab ab ab ab ab ab ab ab ab ab ab ab ab ab ab ab ab ab ab ab ab ab ab ab ab ab ab ab ab ab ab ab ab ab ab ab ab ab ab ab ab ab ab ab ab ab ab ab ab ab ab ab ab | L2: ab ab ab ab ab ab ab ab ab ab ab ab ab ab ab ab ab ab ab ab ab ab ab ab ab ab ab ab ab ab ab ab ab ab ab ab ab ab ab ab ab ab ab ab ab ab ab ab ab ab ab ab ab ab ab ab ab ab ab ab ab ab ab ab ab ab ab ab ab ab ab ab ab ab ab ab ab ab ab ab ab ab ab ab ab ab ab ab ab ab ab ab ab ab ab ab ab ab ab ab ab ab ab ab ab ab ab ab ab ab ab ab ab ab ab ab ab ab ab ab ab ab ab ab ab ab ab ab ab ab ab ab ab ab ab ab ab ab ab ab ab ab ab ab ab ab ab ab ab ab ab ab ab ab ab ab ab ab ab ab ab ab ab ab ab ab ab ab ab ab ab ab ab ab ab ab ab ab ab ab ab ab ab ab ab ab ab ab ab ab ab ab ab ab ab ab ab ab ab ab ab ab ab ab ab ab ab ab ab ab ab ab ab ab ab ab ab ab ab ab ab ab ab ab ab ab ab ab ab ab ab ab ab ab ab ab ab ab ab ab ab ab ab ab ab ab ab ab ab ab ab ab ab ab ab | M2: ab ab ab ab ab ab ab ab ab ab ab ab ab ab ab ab ab ab ab ab ab ab ab ab ab ab ab ab ab ab ab ab ab ab ab ab ab ab ab ab ab ab ab ab ab ab ab ab ab ab ab ab ab ab ab ab ab ab ab ab ab ab ab ab ab ab ab ab ab ab ab ab ab ab ab ab ab ab ab ab ab ab ab ab ab ab ab ab ab ab ab ab ab ab ab ab ab ab ab ab ab ab ab ab ab ab ab ab ab ab ab ab ab ab ab ab ab ab ab ab ab ab ab ab ab ab ab ab ab ab ab ab ab ab ab ab ab ab ab ab ab ab ab ab ab ab ab ab ab ab ab ab ab ab ab ab ab ab ab ab ab ab ab ab ab ab ab ab ab ab ab ab ab ab ab ab ab ab ab ab ab ab ab ab ab ab ab ab ab ab ab ab ab ab ab ab ab ab ab ab ab ab ab ab ab ab ab ab ab ab ab ab ab ab ab ab ab ab ab ab ab ab ab ab ab ab ab ab ab ab ab ab ab ab ab ab ab ab ab ab ab ab ab ab ab ab ab ab ab ab ab ab ab ab ab | N2: ab ab ab ab ab ab ab ab ab ab ab ab ab ab ab ab ab ab ab ab ab ab ab ab ab ab ab ab ab ab ab ab ab ab ab ab ab ab ab ab ab ab ab ab ab ab ab ab ab ab ab ab ab ab ab ab ab ab ab ab ab ab ab ab ab ab ab ab ab ab ab ab ab ab ab ab ab ab ab ab ab ab ab ab ab ab ab ab ab ab ab ab ab ab ab ab ab ab ab ab ab ab ab ab ab ab ab ab ab ab ab ab ab ab ab ab ab ab ab ab ab ab ab ab ab ab ab ab ab ab ab ab ab ab ab ab ab ab ab ab ab ab ab ab ab ab ab ab ab ab ab ab ab ab ab ab ab ab ab ab ab ab ab ab ab ab ab ab ab ab ab ab ab ab ab ab ab ab ab ab ab ab ab ab ab ab ab ab ab ab ab ab ab ab ab ab ab ab ab ab ab ab ab ab ab ab ab ab ab ab ab ab ab ab ab ab ab ab ab ab ab ab ab ab ab ab ab ab ab ab ab ab ab ab ab ab ab ab ab ab ab ab ab ab ab ab ab ab ab ab ab ab ab ab ab | O2: ab ab ab ab ab ab ab ab ab ab ab ab ab ab ab ab ab ab ab ab ab ab ab ab ab ab ab ab ab ab ab ab ab ab ab ab ab ab ab ab ab ab ab ab ab ab ab ab ab ab ab ab ab ab ab ab ab ab ab ab ab ab ab ab ab ab ab ab ab ab ab ab ab ab ab ab ab ab ab ab ab ab ab ab ab ab ab ab ab ab ab ab ab ab ab ab ab ab ab ab ab ab ab ab ab ab ab ab ab ab ab ab ab ab ab ab ab ab ab ab ab ab ab ab ab ab ab ab ab ab ab ab ab ab ab ab ab ab ab ab ab ab ab ab ab ab ab ab ab ab ab ab ab ab ab ab ab ab ab ab ab ab ab ab ab ab ab ab ab ab ab ab ab ab ab ab ab ab ab ab ab ab ab ab ab ab ab ab ab ab ab ab ab ab ab ab ab ab ab ab ab ab ab ab ab ab ab ab ab ab ab ab ab ab ab ab ab ab ab ab ab ab ab ab ab ab ab ab ab ab ab ab ab ab ab ab ab ab ab ab ab ab ab ab ab ab ab ab ab ab ab ab ab ab ab | P2: ab ab ab ab ab ab ab ab ab ab ab ab ab ab ab ab ab ab ab ab ab ab ab ab ab ab ab ab ab ab ab ab ab ab ab ab ab ab ab ab ab ab ab ab ab ab ab ab ab ab ab ab ab ab ab ab ab ab ab ab ab ab ab ab ab ab ab ab ab ab ab ab ab ab ab ab ab ab ab ab ab ab ab ab ab ab ab ab ab ab ab ab ab ab ab ab ab ab ab ab ab ab ab ab ab ab ab ab ab ab ab ab ab ab ab ab ab ab ab ab ab ab ab ab ab ab ab ab ab ab ab ab ab ab ab ab ab ab ab ab ab ab ab ab ab ab ab ab ab ab ab ab ab ab ab ab ab ab ab ab ab ab ab ab ab ab ab ab ab ab ab ab ab ab ab ab ab ab ab ab ab ab ab ab ab ab ab ab ab ab ab ab ab ab ab ab ab ab ab ab ab ab ab ab ab ab ab ab ab ab ab ab ab ab ab ab ab ab ab ab ab ab ab ab ab ab ab ab ab ab ab ab ab ab ab ab ab ab ab ab ab ab ab ab ab ab ab ab ab ab ab ab ab ab ab | Q2: ab ab ab ab ab ab ab ab ab ab ab ab ab ab ab ab ab ab ab ab ab ab ab ab ab ab ab ab ab ab ab ab ab ab ab ab ab ab ab ab ab ab ab ab ab ab ab ab ab ab ab ab ab ab ab ab ab ab ab ab ab ab ab ab ab ab ab ab ab ab ab ab ab ab ab ab ab ab ab ab ab ab ab ab ab ab ab ab ab ab ab ab ab ab ab ab ab ab ab ab ab ab ab ab ab ab ab ab ab ab ab ab ab ab ab ab ab ab ab ab ab ab ab ab ab ab ab ab ab ab ab ab ab ab ab ab ab ab ab ab ab ab ab ab ab ab ab ab ab ab ab ab ab ab ab ab ab ab ab ab ab ab ab ab ab ab ab ab ab ab ab ab ab ab ab ab ab ab ab ab ab ab ab ab ab ab ab ab ab ab ab ab ab ab ab ab ab ab ab ab ab ab ab ab ab ab ab ab ab ab ab ab ab ab ab ab ab ab ab ab ab ab ab ab ab ab ab ab ab ab ab ab ab ab ab ab ab ab ab ab ab ab ab ab ab ab ab ab ab ab ab ab ab ab ab | R2: ab ab ab ab ab ab ab ab ab ab ab ab ab ab ab ab ab ab ab ab ab ab ab ab ab ab ab ab ab ab ab ab ab ab ab ab ab ab ab ab ab ab ab ab ab ab ab ab ab ab ab ab ab ab ab ab ab ab ab ab ab ab ab ab ab ab ab ab ab ab ab ab ab ab ab ab ab ab ab ab ab ab ab ab ab ab ab ab ab ab ab ab ab ab ab ab ab ab ab ab ab ab ab ab ab ab ab ab ab ab ab ab ab ab ab ab ab ab ab ab ab ab ab ab ab ab ab ab ab ab ab ab ab ab ab ab ab ab ab ab ab ab ab ab ab ab ab ab ab ab ab ab ab ab ab ab ab ab ab ab ab ab ab ab ab ab ab ab ab ab ab ab ab ab ab ab ab ab ab ab ab ab ab ab ab ab ab ab ab ab ab ab ab ab ab ab ab ab ab ab ab ab ab ab ab ab ab ab ab ab ab ab ab ab ab ab ab ab ab ab ab ab ab ab ab ab ab ab ab ab ab ab ab ab ab ab ab ab ab ab ab ab ab ab ab ab ab ab ab ab ab ab ab ab ab | S2: ab ab ab ab ab ab ab ab ab ab ab ab ab ab ab ab ab ab ab ab ab ab ab ab ab ab ab ab ab ab ab ab ab ab ab ab ab ab ab ab ab ab ab ab ab ab ab ab ab ab ab ab ab ab ab ab ab ab ab ab ab ab ab ab ab ab ab ab ab ab ab ab ab ab ab ab ab ab ab ab ab ab ab ab ab ab ab ab ab ab ab ab ab ab ab ab ab ab ab ab ab ab ab ab ab ab ab ab ab ab ab ab ab ab ab ab ab ab ab ab ab ab ab ab ab ab ab ab ab ab ab ab ab ab ab ab ab ab ab ab ab ab ab ab ab ab ab ab ab ab ab ab ab ab ab ab ab ab ab ab ab ab ab ab ab ab ab ab ab ab ab ab ab ab ab ab ab ab ab ab ab ab ab ab ab ab ab ab ab ab ab ab ab ab ab ab ab ab ab ab ab ab ab ab ab ab ab ab ab ab ab ab ab ab ab ab ab ab ab ab ab ab ab ab ab ab ab ab ab ab ab ab ab ab ab ab ab ab ab ab ab ab ab ab ab ab ab ab ab ab ab ab ab ab ab | T2: ab ab ab ab ab ab ab ab ab ab ab ab ab ab ab ab ab ab ab ab ab ab ab ab ab ab ab ab ab ab ab ab ab ab ab ab ab ab ab ab ab ab ab ab ab ab ab ab ab ab ab ab ab ab ab ab ab ab ab ab ab ab ab ab ab ab ab ab ab ab ab ab ab ab ab ab ab ab ab ab ab ab ab ab ab ab ab ab ab ab ab ab ab ab ab ab ab ab ab ab ab ab ab ab ab ab ab ab ab ab ab ab ab ab ab ab ab ab ab ab ab ab ab ab ab ab ab ab ab ab ab ab ab ab ab ab ab ab ab ab ab ab ab ab ab ab ab ab ab ab ab ab ab ab ab ab ab ab ab ab ab ab ab ab ab ab ab ab ab ab ab ab ab ab ab ab ab ab ab ab ab ab ab ab ab ab ab ab ab ab ab ab ab ab ab ab ab ab ab ab ab ab ab ab ab ab ab ab ab ab ab ab ab ab ab ab ab ab ab ab ab ab ab ab ab ab ab ab ab ab ab ab ab ab ab ab ab ab ab ab ab ab ab ab ab ab ab ab ab ab ab ab ab ab ab | U2: ab ab ab ab ab ab ab ab ab ab ab ab ab ab ab ab ab ab ab ab ab ab ab ab ab ab ab ab ab ab ab ab ab ab ab ab ab ab ab ab ab ab ab ab ab ab ab ab ab ab ab ab ab ab ab ab ab ab ab ab ab ab ab ab ab ab ab ab ab ab ab ab ab ab ab ab ab ab ab ab ab ab ab ab ab ab ab ab ab ab ab ab ab ab ab ab ab ab ab ab ab ab ab ab ab ab ab ab ab ab ab ab ab ab ab ab ab ab ab ab ab ab ab ab ab ab ab ab ab ab ab ab ab ab ab ab ab ab ab ab ab ab ab ab ab ab ab ab ab ab ab ab ab ab ab ab ab ab ab ab ab ab ab ab ab ab ab ab ab ab ab ab ab ab ab ab ab ab ab ab ab ab ab ab ab ab ab ab ab ab ab ab ab ab ab ab ab ab ab ab ab ab ab ab ab ab ab ab ab ab ab ab ab ab ab ab ab ab ab ab ab ab ab ab ab ab ab ab ab ab ab ab ab ab ab ab ab ab ab ab ab ab ab ab ab ab ab ab ab ab ab ab ab ab ab | V2: ab ab ab ab ab ab ab ab ab ab ab ab ab ab ab ab ab ab ab ab ab ab ab ab ab ab ab ab ab ab ab ab ab ab ab ab ab ab ab ab ab ab ab ab ab ab ab ab ab ab ab ab ab ab ab ab ab ab ab ab ab ab ab ab ab ab ab ab ab ab ab ab ab ab ab ab ab ab ab ab ab ab ab ab ab ab ab ab ab ab ab ab ab ab ab ab ab ab ab ab ab ab ab ab ab ab ab ab ab ab ab ab ab ab ab ab ab ab ab ab ab ab ab ab ab ab ab ab ab ab ab ab ab ab ab ab ab ab ab ab ab ab ab ab ab ab ab ab ab ab ab ab ab ab ab ab ab ab ab ab ab ab ab ab ab ab ab ab ab ab ab ab ab ab ab ab ab ab ab ab ab ab ab ab ab ab ab ab ab ab ab ab ab ab ab ab ab ab ab ab ab ab ab ab ab ab ab ab ab ab ab ab ab ab ab ab ab ab ab ab ab ab ab ab ab ab ab ab ab ab ab ab ab ab ab ab ab ab ab ab ab ab ab ab ab ab ab ab ab ab ab ab ab ab ab | W2: ab ab ab ab ab ab ab ab ab ab ab ab ab ab ab ab ab ab ab ab ab ab ab ab ab ab ab ab ab ab ab ab ab ab ab ab ab ab ab ab ab ab ab ab ab ab ab ab ab ab ab ab ab ab ab ab ab ab ab ab ab ab ab ab ab ab ab ab ab ab ab ab ab ab ab ab ab ab ab ab ab ab ab ab ab ab ab ab ab ab ab ab ab ab ab ab ab ab ab ab ab ab ab ab ab ab ab ab ab ab ab ab ab ab ab ab ab ab ab ab ab ab ab ab ab ab ab ab ab ab ab ab ab ab ab ab ab ab ab ab ab ab ab ab ab ab ab ab ab ab ab ab ab ab ab ab ab ab ab ab ab ab ab ab ab ab ab ab ab ab ab ab ab ab ab ab ab ab ab ab ab ab ab ab ab ab ab ab ab ab ab ab ab ab ab ab ab ab ab ab ab ab ab ab ab ab ab ab ab ab ab ab ab ab ab ab ab ab ab ab ab ab ab ab ab ab ab ab ab ab ab ab ab ab ab ab ab ab ab ab ab ab ab ab ab ab ab ab ab ab ab ab ab ab ab | X2: ab ab ab ab ab ab ab ab ab ab ab ab ab ab ab ab ab ab ab ab ab ab ab ab ab ab ab ab ab ab ab ab ab ab ab ab ab ab ab ab ab ab ab ab ab ab ab ab ab ab ab ab ab ab ab ab ab ab ab ab ab ab ab ab ab ab ab ab ab ab ab ab ab ab ab ab ab ab ab ab ab ab ab ab ab ab ab ab ab ab ab ab ab ab ab ab ab ab ab ab ab ab ab ab ab ab ab ab ab ab ab ab ab ab ab ab ab ab ab ab ab ab ab ab ab ab ab ab ab ab ab ab ab ab ab ab ab ab ab ab ab ab ab ab ab ab ab ab ab ab ab ab ab ab ab ab ab ab ab ab ab ab ab ab ab ab ab ab ab ab ab ab ab ab ab ab ab ab ab ab ab ab ab ab ab ab ab ab ab ab ab ab ab ab ab ab ab ab ab ab ab ab ab ab ab ab ab ab ab ab ab ab ab ab ab ab ab ab ab ab ab ab ab ab ab ab ab ab ab ab ab ab ab ab ab ab ab ab ab ab ab ab ab ab ab ab ab ab ab ab ab ab ab ab ab
A3: =ROW() -> 3 | B3: =VLOOKUP(ROW(),data,COLUMN(),0) -> 0 | C3: =VLOOKUP(ROW(),data,COLUMN(),0) -> 0 | D3: =" ngày "&TEXT(VLOOKUP(ROW(),data,COLUMN(),0),"dd")&" tháng "&TEXT(VLOOKUP(ROW(),data,COLUMN(),0),"MM")&" năm "&TEXT(VLOOKUP(ROW(),data,COLUMN(),0),"yyyy") -> ngày 00 tháng 01 năm 1900 | E3: =" ngày "&TEXT(VLOOKUP(ROW(),data,COLUMN(),0),"dd")&" tháng "&TEXT(VLOOKUP(ROW(),data,COLUMN(),0),"MM")&" năm "&TEXT(VLOOKUP(ROW(),data,COLUMN(),0),"yyyy") -> ngày 00 tháng 01 năm 1900 | F3: =VLOOKUP(ROW(),data,COLUMN(),0) -> 0 | G3: =VLOOKUP(ROW(),data,COLUMN(),0) -> 0 | H3: =TEXT(VLOOKUP(ROW(),data,COLUMN(),0),"#.##0") -> 0 | I3: =VLOOKUP(ROW(),data,COLUMN(),0) -> 0 | J3: =TEXT(VLOOKUP(ROW(),data,COLUMN(),0),"dd/MM/yyyy") -> 00/01/1900 | K3: =TEXT(VLOOKUP(ROW(),data,COLUMN(),0),"dd/MM/yyyy") -> Xe cẩu 5T: 02 xe. Kích tăng dây: 4 cái. Kìm ép thủy lực: 3 cái. Puly: 6 cái. Các dụng cụ khác như cle, mỏ lết, cuốc, xà beng … | L3: =TEXT(VLOOKUP(ROW(),data,COLUMN(),0),"dd/MM/yyyy") -> FCO và MCCB TBA Minh Khai 1 | M3: =TEXT(VLOOKUP(ROW(),data,COLUMN(),0),"dd/MM/yyyy") -> Tại TBA Minh Khai 1 | N3: =TEXT(VLOOKUP(ROW(),data,COLUMN(),0),"dd/MM/yyyy") -> Đã tiếp địa, Cấm đóng điện | O3: =TEXT(VLOOKUP(ROW(),data,COLUMN(),0),"dd/MM/yyyy") -> Trực tiếp | P3: =TEXT(VLOOKUP(ROW(),data,COLUMN(),0),"dd/MM/yyyy") -> Đơn vị công tác 1: Thực hiện công tác theo PCT/LCT............. Nội dung công việc: thực hiện trong phạm vi từ trụ 03/01 đến trụ 03/11 | Q3: =TEXT(VLOOKUP(ROW(),data,COLUMN(),0),"dd/MM/yyyy") -> Không | ... X3: =TEXT(VLOOKUP(ROW(),data,COLUMN(),0),"dd/MM/yyyy") -> 00/01/1900
A4: =ROW() -> 4 | B4: =VLOOKUP(ROW(),data,COLUMN(),0) -> Di dời hệ thống điện trung hạ thế, trạm biến áp - thuộc dự án: Đường Nguyễn Thị Minh Khai, Huyện Xuân Lộc | C4: =VLOOKUP(ROW(),data,COLUMN(),0) -> Di dời lưới hạ thế ABC độc lập | D4: =" ngày "&TEXT(VLOOKUP(ROW(),data,COLUMN(),0),"dd")&" tháng "&TEXT(VLOOKUP(ROW(),data,COLUMN(),0),"MM")&" năm "&TEXT(VLOOKUP(ROW(),data,COLUMN(),0),"yyyy") -> ngày 30 tháng 08 năm 2020 | E4: =" ngày "&TEXT(VLOOKUP(ROW(),data,COLUMN(),0),"dd")&" tháng "&TEXT(VLOOKUP(ROW(),data,COLUMN(),0),"MM")&" năm "&TEXT(VLOOKUP(ROW(),data,COLUMN(),0),"yyyy") -> ngày 30 tháng 08 năm 2020 | F4: =VLOOKUP(ROW(),data,COLUMN(),0) -> Lưới hạ thế độc lập sau TBA Minh Khai 1 | G4: =VLOOKUP(ROW(),data,COLUMN(),0) -> Di dời 11 trụ hạ thế từ trụ 03/01 đến trụ 03/11 và toàn bộ dây khách hàng đấu nối vào lưới hạ thế hiện hữu | H4: =TEXT(VLOOKUP(ROW(),data,COLUMN(),0),"#.##0") -> Sử dụng lại toàn bộ vật tư hiện hữu | I4: =VLOOKUP(ROW(),data,COLUMN(),0) -> Dây đai an toàn, quần, áo, nón bảo hộ lao động… Găng tay hạ thế | J4: =TEXT(VLOOKUP(ROW(),data,COLUMN(),0),"dd/MM/yyyy") -> Amper kìm, máy đo điện trở tiếp địa… | K4: =TEXT(VLOOKUP(ROW(),data,COLUMN(),0),"dd/MM/yyyy") -> Xe cẩu 5T: 02 xe. Kích tăng dây: 4 cái. Kìm ép thủy lực: 3 cái. Puly: 6 cái. Các dụng cụ khác như cle, mỏ lết, cuốc, xà beng … | L4: =TEXT(VLOOKUP(ROW(),data,COLUMN(),0),"dd/MM/yyyy") -> FCO và MCCB TBA Minh Khai 1 | M4: =TEXT(VLOOKUP(ROW(),data,COLUMN(),0),"dd/MM/yyyy") -> Tại TBA Minh Khai 1 | N4: =TEXT(VLOOKUP(ROW(),data,COLUMN(),0),"dd/MM/yyyy") -> Đã tiếp địa, Cấm đóng điện | O4: =TEXT(VLOOKUP(ROW(),data,COLUMN(),0),"dd/MM/yyyy") -> Trực tiếp | P4: =TEXT(VLOOKUP(ROW(),data,COLUMN(),0),"dd/MM/yyyy") -> Đơn vị công tác 1: Thực hiện công tác theo PCT/LCT............. Nội dung công việc: thực hiện trong phạm vi từ trụ 03/01 đến trụ 03/11 | Q4: =TEXT(VLOOKUP(ROW(),data,COLUMN(),0),"dd/MM/yyyy") -> Không | ... X4: =TEXT(VLOOKUP(ROW(),data,COLUMN(),0),"dd/MM/yyyy") -> 00/01/1900

Sheet DS_CongNhan
C1: STT | D1: Họ và tên | E1: Bậc AT | F1: Làm biện pháp an toàn | G1: Làm tại vị trí phức tạp | H1: Ghi chú | I1: Chức danh | J1: Ghi chú | M1: 1 | N1: Nhánh rẽ Thọ Vực
C2: =ROW()-1 -> 1 | D2: =IFERROR(VLOOKUP($C2,NhanSu,2,),"") -> Mai Văn Thái | I2: =IFERROR(VLOOKUP($C2,NhanSu,5,),"") -> Công nhân | L2: ="Giao ông "&D2&" làm "&LOWER(F2)&" trụ trung hạ thế trạm "&M2&" "&$N$1 -> Giao ông Mai Văn Thái làm trụ trung hạ thế trạm 0 Nhánh rẽ Thọ Vực | M2: {=INDEX(N:R,ROW(),1)} -> 0
C3: =ROW()-1 -> 2 | D3: =IFERROR(VLOOKUP($C3,NhanSu,2,),"") -> Đinh Minh Hòa | E3: =IFERROR(VLOOKUP($C3,NhanSu,3,),"") -> 44015 | I3: =IFERROR(VLOOKUP($C3,NhanSu,5,),"") -> Công nhân | L3: ="Giao ông "&D3&" làm "&LOWER(F3)&" trụ trung hạ thế trạm "&M3&" "&$N$1 -> Giao ông Đinh Minh Hòa làm trụ trung hạ thế trạm 0 Nhánh rẽ Thọ Vực | M3: {=INDEX(N:R,ROW(),1)} -> 0
C4: =ROW()-1 -> 3 | D4: =IFERROR(VLOOKUP($C4,NhanSu,2,),"") -> Đinh Nguyễn Trọng Toàn | E4: =IFERROR(VLOOKUP($C4,NhanSu,3,),"") -> 44015 | I4: =IFERROR(VLOOKUP($C4,NhanSu,5,),"") -> Công nhân | L4: ="Giao ông "&D4&" làm "&LOWER(F4)&" trụ trung hạ thế trạm "&M4&" "&$N$1 -> Giao ông Đinh Nguyễn Trọng Toàn làm trụ trung hạ thế trạm 0 Nhánh rẽ Thọ Vực | M4: {=INDEX(N:R,ROW(),1)} -> 0
C5: =ROW()-1 -> 4 | D5: =IFERROR(VLOOKUP($C5,NhanSu,2,),"") -> Huỳnh Chí Tâm | E5: =IFERROR(VLOOKUP($C5,NhanSu,3,),"") -> 44015 | G5: Trụ đấu nối | I5: =IFERROR(VLOOKUP($C5,NhanSu,5,),"") -> Công nhân | L5: ="Giao ông "&D5&" làm "&LOWER(F5)&" trụ trung hạ thế trạm "&M5&" "&$N$1 -> Giao ông Huỳnh Chí Tâm làm trụ trung hạ thế trạm 0 Nhánh rẽ Thọ Vực | M5: {=INDEX(N:R,ROW(),1)} -> 0
C6: =ROW()-1 -> 5 | D6: =IFERROR(VLOOKUP($C6,NhanSu,2,),"") -> Huỳnh Mạnh Quyền | E6: =IFERROR(VLOOKUP($C6,NhanSu,3,),"") -> 44016 | F6: Tiếp địa | I6: =IFERROR(VLOOKUP($C6,NhanSu,5,),"") -> Công nhân | L6: ="Giao ông "&D6&" làm "&LOWER(F6)&" trụ trung hạ thế trạm "&M6&" "&$N$1 -> Giao ông Huỳnh Mạnh Quyền làm tiếp địa trụ trung hạ thế trạm 029, 041/001B Nhánh rẽ Thọ Vực | M6: {=INDEX(N:R,ROW(),1)} -> 029, 041/001B | N6: 029, 041/001B
C7: =ROW()-1 -> 6 | D7: =IFERROR(VLOOKUP($C7,NhanSu,2,),"") -> Huỳnh Tấn Sơn | E7: =IFERROR(VLOOKUP($C7,NhanSu,3,),"") -> 44016 | I7: =IFERROR(VLOOKUP($C7,NhanSu,5,),"") -> Công nhân | L7: ="Giao ông "&D7&" làm "&LOWER(F7)&" trụ trung hạ thế trạm "&M7&" "&$N$1 -> Giao ông Huỳnh Tấn Sơn làm trụ trung hạ thế trạm 0 Nhánh rẽ Thọ Vực | M7: {=INDEX(N:R,ROW(),1)} -> 0
B8: CHTT | C8: =ROW()-1 -> 7 | D8: =IFERROR(VLOOKUP($C8,NhanSu,2,),"") -> Lê Hoàng Vũ | E8: =IFERROR(VLOOKUP($C8,NhanSu,3,),"") -> 44015 | I8: =IFERROR(VLOOKUP($C8,NhanSu,5,),"") -> Công nhân | L8: ="Giao ông "&D8&" làm "&LOWER(F8)&" trụ trung hạ thế trạm "&M8&" "&$N$1 -> Giao ông Lê Hoàng Vũ làm trụ trung hạ thế trạm 0 Nhánh rẽ Thọ Vực | M8: {=INDEX(N:R,ROW(),1)} -> 0
C9: =ROW()-1 -> 8 | D9: =IFERROR(VLOOKUP($C9,NhanSu,2,),"") -> Ngô Minh Nhật | E9: =IFERROR(VLOOKUP($C9,NhanSu,3,),"") -> 44015 | F9: Tiếp địa | I9: =IFERROR(VLOOKUP($C9,NhanSu,5,),"") -> Công nhân | L9: ="Giao ông "&D9&" làm "&LOWER(F9)&" trụ trung hạ thế trạm "&M9&" "&$N$1 -> Giao ông Ngô Minh Nhật làm tiếp địa trụ trung hạ thế trạm 054, 055 Nhánh rẽ Thọ Vực | M9: {=INDEX(N:R,ROW(),1)} -> 054, 055 | N9: 054, 055
C10: =ROW()-1 -> 9 | D10: =IFERROR(VLOOKUP($C10,NhanSu,2,),"") -> Nguyễn Trọng Hữu | E10: =IFERROR(VLOOKUP($C10,NhanSu,3,),"") -> 44015 | I10: =IFERROR(VLOOKUP($C10,NhanSu,5,),"") -> Công nhân | L10: ="Giao ông "&D10&" làm "&LOWER(F10)&" trụ trung hạ thế trạm "&M10&" "&$N$1 -> Giao ông Nguyễn Trọng Hữu làm trụ trung hạ thế trạm 0 Nhánh rẽ Thọ Vực | M10: {=INDEX(N:R,ROW(),1)} -> 0
C11: =ROW()-1 -> 10 | D11: =IFERROR(VLOOKUP($C11,NhanSu,2,),"") -> Phạm Nguyễn Hoàng Phi | E11: =IFERROR(VLOOKUP($C11,NhanSu,3,),"") -> 44015 | F11: Tiếp địa | I11: =IFERROR(VLOOKUP($C11,NhanSu,5,),"") -> Công nhân | L11: ="Giao ông "&D11&" làm "&LOWER(F11)&" trụ trung hạ thế trạm "&M11&" "&$N$1 -> Giao ông Phạm Nguyễn Hoàng Phi làm tiếp địa trụ trung hạ thế trạm trụ 010A Nhánh rẽ Thọ Vực | M11: {=INDEX(N:R,ROW(),1)} -> trụ 010A | N11: trụ 010A
C12: =ROW()-1 -> 11 | D12: =IFERROR(VLOOKUP($C12,NhanSu,2,),"") | E12: =IFERROR(VLOOKUP($C12,NhanSu,3,),"") | I12: =IFERROR(VLOOKUP($C12,NhanSu,5,),"") | L12: ="Giao ông "&D12&" làm "&LOWER(F12)&" trụ trung hạ thế trạm "&M12&" "&$N$1 -> Giao ông làm trụ trung hạ thế trạm 0 Nhánh rẽ Thọ Vực | M12: {=INDEX(N:R,ROW(),1)} -> 0
C13: =ROW()-1 -> 12 | D13: =IFERROR(VLOOKUP($C13,NhanSu,2,),"") | E13: =IFERROR(VLOOKUP($C13,NhanSu,3,),"") | F13: Tiếp địa | I13: =IFERROR(VLOOKUP($C13,NhanSu,5,),"") | L13: ="Giao ông "&D13&" làm "&LOWER(F13)&" trụ trung hạ thế trạm "&M13&" "&$N$1 -> Giao ông làm tiếp địa trụ trung hạ thế trạm Thọ Vực 2, Thọ Vực 2A, Thọ Vực 3 Nhánh rẽ Thọ Vực | M13: {=INDEX(N:R,ROW(),1)} -> Thọ Vực 2, Thọ Vực 2A, Thọ Vực 3 | N13: Thọ Vực 2, Thọ Vực 2A, Thọ Vực 3
C14: =ROW()-1 -> 13 | D14: =IFERROR(VLOOKUP($C14,NhanSu,2,),"") | E14: =IFERROR(VLOOKUP($C14,NhanSu,3,),"") | G14: Trụ đấu nối | I14: =IFERROR(VLOOKUP($C14,NhanSu,5,),"") | L14: ="Giao ông "&D14&" làm "&LOWER(F14)&" trụ trung hạ thế trạm "&M14&" "&$N$1 -> Giao ông làm trụ trung hạ thế trạm 0 Nhánh rẽ Thọ Vực | M14: {=INDEX(N:R,ROW(),1)} -> 0
B15: CHTT | C15: =ROW()-1 -> 14 | D15: =IFERROR(VLOOKUP($C15,NhanSu,2,),"") | E15: =IFERROR(VLOOKUP($C15,NhanSu,3,),"") | F15: Tiếp địa | I15: =IFERROR(VLOOKUP($C15,NhanSu,5,),"") | L15: ="Giao ông "&D15&" làm "&LOWER(F15)&" trụ trung hạ thế trạm "&M15&" "&$N$1 -> Giao ông làm tiếp địa trụ trung hạ thế trạm Nông trường Thọ Vực 1, Nông trường Thọ Vực 2. Nhánh rẽ Thọ Vực | M15: {=INDEX(N:R,ROW(),1)} -> Nông trường Thọ Vực 1, Nông trường Thọ Vực 2. | N15: Nông trường Thọ Vực 1, Nông trường Thọ Vực 2.
C16: =ROW()-1 -> 15 | D16: =IFERROR(VLOOKUP($C16,NhanSu,2,),"") | E16: =IFERROR(VLOOKUP($C16,NhanSu,3,),"") | I16: =IFERROR(VLOOKUP($C16,NhanSu,5,),"") | L16: ="Giao ông "&D16&" làm "&LOWER(F16)&" trụ trung hạ thế trạm "&M16&" "&$N$1 -> Giao ông làm trụ trung hạ thế trạm 0 Nhánh rẽ Thọ Vực | M16: {=INDEX(N:R,ROW(),1)} -> 0
C17: =ROW()-1 -> 16 | D17: =IFERROR(VLOOKUP($C17,NhanSu,2,),"") | E17: =IFERROR(VLOOKUP($C17,NhanSu,3,),"") | F17: Tiếp địa | I17: =IFERROR(VLOOKUP($C17,NhanSu,5,),"") | L17: ="Giao ông "&D17&" làm "&LOWER(F17)&" trụ trung hạ thế trạm "&M17&" "&$N$1 -> Giao ông làm tiếp địa trụ trung hạ thế trạm 054/001 Nhánh rẽ Thọ Vực | M17: {=INDEX(N:R,ROW(),1)} -> 054/001 | N17: 054/001
C18: =ROW()-1 -> 17 | D18: =IFERROR(VLOOKUP($C18,NhanSu,2,),"") | E18: =IFERROR(VLOOKUP($C18,NhanSu,3,),"") | I18: =IFERROR(VLOOKUP($C18,NhanSu,5,),"") | L18: ="Giao ông "&D18&" làm "&LOWER(F18)&" trụ trung hạ thế trạm "&M18&" "&$N$1 -> Giao ông làm trụ trung hạ thế trạm 0 Nhánh rẽ Thọ Vực | M18: {=INDEX(N:R,ROW(),1)} -> 0
C19: =ROW()-1 -> 18 | D19: =IFERROR(VLOOKUP($C19,NhanSu,2,),"") | E19: =IFERROR(VLOOKUP($C19,NhanSu,3,),"") | F19: Tiếp địa | G19: Trụ đấu nối | I19: =IFERROR(VLOOKUP($C19,NhanSu,5,),"") | L19: ="Giao ông "&D19&" làm "&LOWER(F19)&" trụ trung hạ thế trạm "&M19&" "&$N$1 -> Giao ông làm tiếp địa trụ trung hạ thế trạm 001A Nhánh rẽ Thọ Vực | M19: {=INDEX(N:R,ROW(),1)} -> 001A | N19: 001A
C20: =ROW()-1 -> 19 | D20: =IFERROR(VLOOKUP($C20,NhanSu,2,),"") | E20: =IFERROR(VLOOKUP($C20,NhanSu,3,),"") | I20: =IFERROR(VLOOKUP($C20,NhanSu,5,),"") | L20: ="Giao ông "&D20&" làm "&LOWER(F20)&" trụ trung hạ thế trạm "&M20&" "&$N$1 -> Giao ông làm trụ trung hạ thế trạm 0 Nhánh rẽ Thọ Vực | M20: {=INDEX(N:R,ROW(),1)} -> 0
B21: CHTT | C21: =ROW()-1 -> 20 | D21: =IFERROR(VLOOKUP($C21,NhanSu,2,),"") | E21: =IFERROR(VLOOKUP($C21,NhanSu,3,),"") | I21: =IFERROR(VLOOKUP($C21,NhanSu,5,),"") | L21: ="Giao ông "&D21&" làm "&LOWER(F21)&" trụ trung hạ thế trạm "&M21&" "&$N$1 -> Giao ông làm trụ trung hạ thế trạm 0 Nhánh rẽ Thọ Vực | M21: {=INDEX(N:R,ROW(),1)} -> 0
C22: =ROW()-1 -> 21 | D22: =IFERROR(VLOOKUP($C22,NhanSu,2,),"") | E22: =IFERROR(VLOOKUP($C22,NhanSu,3,),"") | I22: =IFERROR(VLOOKUP($C22,NhanSu,5,),"") | L22: ="Giao ông "&D22&" làm "&LOWER(F22)&" trụ trung hạ thế trạm "&M22&" "&$N$1 -> Giao ông làm trụ trung hạ thế trạm 0 Nhánh rẽ Thọ Vực | M22: {=INDEX(N:R,ROW(),1)} -> 0
C23: =ROW()-1 -> 22 | D23: =IFERROR(VLOOKUP($C23,NhanSu,2,),"") | E23: =IFERROR(VLOOKUP($C23,NhanSu,3,),"") | G23: Trụ đấu nối | I23: =IFERROR(VLOOKUP($C23,NhanSu,5,),"") | L23: ="Giao ông "&D23&" làm "&LOWER(F23)&" trụ trung hạ thế trạm "&M23&" "&$N$1 -> Giao ông làm trụ trung hạ thế trạm 0 Nhánh rẽ Thọ Vực | M23: {=INDEX(N:R,ROW(),1)} -> 0
C24: =ROW()-1 -> 23 | D24: =IFERROR(VLOOKUP($C24,NhanSu,2,),"") | E24: =IFERROR(VLOOKUP($C24,NhanSu,3,),"") | I24: =IFERROR(VLOOKUP($C24,NhanSu,5,),"") | L24: ="Giao ông "&D24&" làm "&LOWER(F24)&" trụ trung hạ thế trạm "&M24&" "&$N$1 -> Giao ông làm trụ trung hạ thế trạm 0 Nhánh rẽ Thọ Vực | M24: {=INDEX(N:R,ROW(),1)} -> 0
C25: =ROW()-1 -> 24 | D25: =IFERROR(VLOOKUP($C25,NhanSu,2,),"") | E25: =IFERROR(VLOOKUP($C25,NhanSu,3,),"") | I25: =IFERROR(VLOOKUP($C25,NhanSu,5,),"") | L25: ="Giao ông "&D25&" làm "&LOWER(F25)&" trụ trung hạ thế trạm "&M25&" "&$N$1 -> Giao ông làm trụ trung hạ thế trạm 0 Nhánh rẽ Thọ Vực | M25: {=INDEX(N:R,ROW(),1)} -> 0
C26: =ROW()-1 -> 25 | D26: =IFERROR(VLOOKUP($C26,NhanSu,2,),"") | E26: =IFERROR(VLOOKUP($C26,NhanSu,3,),"") | I26: =IFERROR(VLOOKUP($C26,NhanSu,5,),"") | L26: ="Giao ông "&D26&" làm "&LOWER(F26)&" trụ trung hạ thế trạm "&M26&" "&$N$1 -> Giao ông làm trụ trung hạ thế trạm 0 Nhánh rẽ Thọ Vực | M26: {=INDEX(N:R,ROW(),1)} -> 0
C27: =ROW()-1 -> 26 | D27: =IFERROR(VLOOKUP($C27,NhanSu,2,),"") | E27: =IFERROR(VLOOKUP($C27,NhanSu,3,),"") | I27: =IFERROR(VLOOKUP($C27,NhanSu,5,),"") | L27: ="Giao ông "&D27&" làm "&LOWER(F27)&" trụ trung hạ thế trạm "&M27&" "&$N$1 -> Giao ông làm trụ trung hạ thế trạm 0 Nhánh rẽ Thọ Vực | M27: {=INDEX(N:R,ROW(),1)} -> 0

Sheet NhanSu
C1: x | D1: TT | E1: Họ và tên | F1: Bậc thợ | G1: Bậc AT | H1: Chức danh | I1: Ghi chú | J1: 4 | K1: Minh Khai | L1: Thọ Vực | M1: 20200880312 | N1: 20200401924 | O1: =COLUMN()-COLUMN($J$1) -> 5 | P1: =COLUMN()-COLUMN($J$1) -> 6 | Q1: =COLUMN()-COLUMN($J$1) -> 7
C2: x | D2: =SUM($J$2:J2) -> 0 | E2: Đinh Nguyễn Trung Hiếu | H2: Chỉ huy trưởng | J2: {=INDEX(K:Q,ROW(),$J$1)} -> 0 | M2: 1
C3: x | D3: =SUM($J$2:J3) -> 0 | E3: Đinh Minh Trí | H3: Giám sát kỹ thuật | J3: {=INDEX(K:Q,ROW(),$J$1)} -> 0 | M3: 1
C4: x | D4: =SUM($J$2:J4) -> 1 | E4: Mai Văn Thái | F4: 44015 | G4: 43956 | H4: Công nhân | J4: {=INDEX(K:Q,ROW(),$J$1)} -> 1 | K4: 1 | L4: 1 | N4: 1
C5: x | D5: =SUM($J$2:J5) -> 2 | E5: Đinh Minh Hòa | F5: 44015 | G5: 43954 | H5: Công nhân | J5: {=INDEX(K:Q,ROW(),$J$1)} -> 1 | K5: 1 | L5: 1 | M5: 1 | N5: 1
C6: x | D6: =SUM($J$2:J6) -> 3 | E6: Đinh Nguyễn Trọng Toàn | F6: 44015 | G6: 43955 | H6: Công nhân | J6: {=INDEX(K:Q,ROW(),$J$1)} -> 1 | K6: 1 | L6: 1 | N6: 1
C7: x | D7: =SUM($J$2:J7) -> 3 | E7: Đinh Văn Chức | F7: 44016 | G7: 43955 | H7: Công nhân | J7: {=INDEX(K:Q,ROW(),$J$1)} -> 0 | K7: 1 | L7: 1
C8: x | D8: =SUM($J$2:J8) -> 3 | E8: Đỗ Sơn Lâm | F8: 44015 | G8: 43955 | H8: Công nhân | J8: {=INDEX(K:Q,ROW(),$J$1)} -> 0 | K8: 1 | L8: 1 | M8: 1
C9: x | D9: =SUM($J$2:J9) -> 4 | E9: Huỳnh Chí Tâm | F9: 44015 | G9: 43956 | H9: Công nhân | J9: {=INDEX(K:Q,ROW(),$J$1)} -> 1 | K9: 1 | L9: 1 | M9: 1 | N9: 1
C10: x | D10: =SUM($J$2:J10) -> 5 | E10: Huỳnh Mạnh Quyền | F10: 44016 | G10: 43955 | H10: Công nhân | J10: {=INDEX(K:Q,ROW(),$J$1)} -> 1 | K10: 1 | L10: 1 | M10: 1 | N10: 1
C11: x | D11: =SUM($J$2:J11) -> 6 | E11: Huỳnh Tấn Sơn | F11: 44016 | G11: 43955 | H11: Công nhân | J11: {=INDEX(K:Q,ROW(),$J$1)} -> 1 | K11: 1 | L11: 1 | M11: 1 | N11: 1
C12: x | D12: =SUM($J$2:J12) -> 7 | E12: Lê Hoàng Vũ | F12: 44015 | G12: 43954 | H12: Công nhân | J12: {=INDEX(K:Q,ROW(),$J$1)} -> 1 | K12: 1 | L12: 1 | M12: 1 | N12: 1
C13: x | D13: =SUM($J$2:J13) -> 8 | E13: Ngô Minh Nhật | F13: 44015 | G13: 43954 | H13: Công nhân | J13: {=INDEX(K:Q,ROW(),$J$1)} -> 1 | K13: 1 | L13: 1 | M13: 1 | N13: 1
C14: x | D14: =SUM($J$2:J14) -> 8 | E14: Nguyễn Hoàng Dương Khang | F14: 44015 | G14: 43954 | H14: Công nhân | J14: {=INDEX(K:Q,ROW(),$J$1)} -> 0 | K14: 1 | L14: 1 | M14: 1
C15: x | D15: =SUM($J$2:J15) -> 8 | E15: Nguyễn Hoàng Tú | F15: 44015 | G15: 43955 | H15: Công nhân | J15: {=INDEX(K:Q,ROW(),$J$1)} -> 0 | K15: 1 | L15: 1 | M15: 1
C16: x | D16: =SUM($J$2:J16) -> 8 | E16: Nguyễn Ngọc Sơn | F16: 44015 | G16: 43955 | H16: Công nhân | J16: {=INDEX(K:Q,ROW(),$J$1)} -> 0 | K16: 1 | L16: 1
C17: x | D17: =SUM($J$2:J17) -> 8 | E17: Nguyễn Nhật Khánh | F17: 44015 | G17: 43954 | H17: Công nhân | J17: {=INDEX(K:Q,ROW(),$J$1)} -> 0 | K17: 1 | L17: 1
C18: x | D18: =SUM($J$2:J18) -> 8 | E18: Nguyễn Tân Long | F18: 44015 | G18: 43956 | H18: Công nhân | J18: {=INDEX(K:Q,ROW(),$J$1)} -> 0 | K18: 1 | L18: 1
C19: x | D19: =SUM($J$2:J19) -> 9 | E19: Nguyễn Trọng Hữu | F19: 44015 | G19: 43954 | H19: Công nhân | J19: {=INDEX(K:Q,ROW(),$J$1)} -> 1 | K19: 1 | L19: 1 | M19: 1 | N19: 1
C20: x | D20: =SUM($J$2:J20) -> 9 | E20: Nguyễn Văn Hoàng Nam | F20: 44015 | G20: 43955 | H20: Công nhân | J20: {=INDEX(K:Q,ROW(),$J$1)} -> 0 | K20: 1 | L20: 1 | M20: 1
C21: x | D21: =SUM($J$2:J21) -> 10 | E21: Phạm Nguyễn Hoàng Phi | F21: 44015 | G21: 43954 | H21: Công nhân | J21: {=INDEX(K:Q,ROW(),$J$1)} -> 1 | K21: 1 | L21: 1 | M21: 1 | N21: 1
C22: x | D22: =SUM($J$2:J22) -> 10 | E22: Trần Hoàn Thái | F22: 44015 | G22: 43954 | H22: Công nhân | J22: {=INDEX(K:Q,ROW(),$J$1)} -> 0 | K22: 1 | L22: 1 | M22: 1
C23: x | D23: =SUM($J$2:J23) -> 10 | E23: Trần Hoàng Thiện | F23: 44015 | G23: 43954 | H23: Công nhân | J23: {=INDEX(K:Q,ROW(),$J$1)} -> 0 | K23: 1 | L23: 1 | M23: 1
D24: =SUM($J$2:J24) -> 10 | E24: Đinh Minh Cảnh | F24: 44016 | H24: Công nhân | J24: {=INDEX(K:Q,ROW(),$J$1)} -> 0
D25: =SUM($J$2:J25) -> 10 | E25: Đinh Văn Cường | F25: 44014 | H25: Công nhân | J25: {=INDEX(K:Q,ROW(),$J$1)} -> 0
D26: =SUM($J$2:J26) -> 10 | E26: Đinh Xuân Dũng | F26: 44016 | G26: 43956 | H26: Công nhân | J26: {=INDEX(K:Q,ROW(),$J$1)} -> 0 | L26: 1
D27: =SUM($J$2:J27) -> 10 | E27: Hồ Văn Bình | F27: 44016 | G27: 43955 | H27: Công nhân | J27: {=INDEX(K:Q,ROW(),$J$1)} -> 0 | L27: 1
D28: =SUM($J$2:J28) -> 10 | E28: Hồ Văn Cường | F28: 44014 | H28: Công nhân | J28: {=INDEX(K:Q,ROW(),$J$1)} -> 0
D29: =SUM($J$2:J29) -> 10 | E29: Hoàng Như Hoàn | H29: Giám sát kỹ thuật | J29: {=INDEX(K:Q,ROW(),$J$1)} -> 0
D30: =SUM($J$2:J30) -> 10 | E30: Hoàng Văn Long | F30: 44014 | H30: Công nhân | J30: {=INDEX(K:Q,ROW(),$J$1)} -> 0
D31: =SUM($J$2:J31) -> 10 | E31: Hoàng Văn Minh | F31: 44014 | H31: Công nhân | J31: {=INDEX(K:Q,ROW(),$J$1)} -> 0
D32: =SUM($J$2:J32) -> 10 | E32: Lê Văn Xin | F32: 44014 | H32: Công nhân | J32: {=INDEX(K:Q,ROW(),$J$1)} -> 0
D33: =SUM($J$2:J33) -> 10 | E33: Lộc Văn Hòa | F33: 44014 | H33: Công nhân | J33: {=INDEX(K:Q,ROW(),$J$1)} -> 0
D34: =SUM($J$2:J34) -> 10 | E34: Lưu Trọng Hiếu | F34: 44015 | H34: Công nhân | J34: {=INDEX(K:Q,ROW(),$J$1)} -> 0
D35: =SUM($J$2:J35) -> 10 | E35: Nguyễn Anh Tú | G35: 43955 | H35: Giám sát kỹ thuật | J35: {=INDEX(K:Q,ROW(),$J$1)} -> 0 | K35: 1 | L35: 1
D36: =SUM($J$2:J36) -> 10 | E36: Nguyễn Hữu Chung | F36: 44014 | H36: Công nhân | J36: {=INDEX(K:Q,ROW(),$J$1)} -> 0
D37: =SUM($J$2:J37) -> 10 | E37: Nguyễn Huy Quang | J37: {=INDEX(K:Q,ROW(),$J$1)} -> 0
D38: =SUM($J$2:J38) -> 10 | E38: Nguyễn Minh Hiếu | F38: 44014 | H38: Công nhân | J38: {=INDEX(K:Q,ROW(),$J$1)} -> 0
D39: =SUM($J$2:J39) -> 10 | E39: Nguyễn Ngọc Châu | J39: {=INDEX(K:Q,ROW(),$J$1)} -> 0
D40: =SUM($J$2:J40) -> 10 | E40: Nguyễn Ngọc Thuận | F40: 44016 | G40: 43955 | H40: Công nhân | J40: {=INDEX(K:Q,ROW(),$J$1)} -> 0 | L40: 1
...

Sheet KhaoSatHienTruong
A1: x | B1: DonVi | C1: NgayKhaoSat | D1: ChiHuyTrucTiep | E1: PHẠM VI CẮT ĐIỆN | F1: NoiDungCongTac | G1: PhamViLamViec | H1: Thời gian | I1: Cắt | J1: ThietBiDongCat | K1: QLVH-AT | L1: DVTC-AT | M1: Ngày đăng ký | N1: Ngày dự kiến | O1: BienPhapKyThuat | P1: Bảo vệ | Q1: KHU VỰC | R1: THỜI GIAN DỰ KIẾN CẮT ĐIỆN | S1: ĐƠN VỊ CÔNG TÁC | T1: Thứ | U1: Khu vực | V1: KhoiLuong | W1: ThietBiDongCat | X1: ViTriTiepDia
A2: =COLUMN() -> 1 | C2: sda | E2: =COLUMN() -> 5 | F2: =COLUMN() -> 6 | G2: =COLUMN() -> 7 | H2: =COLUMN() -> 8 | I2: =COLUMN() -> 9 | K2: =COLUMN() -> 11 | L2: =COLUMN() -> 12 | M2: =COLUMN() -> 13 | N2: =COLUMN() -> 14 | O2: =COLUMN() -> 15 | P2: =COLUMN() -> 16 | Q2: =COLUMN() -> 17 | R2: =COLUMN() -> 18 | ... X2: =COLUMN() -> 24
B4: Điện lực Cẩm Mỹ | C4: 44259 | D4: Mai Văn Thái | E4: Nhánh rẽ Láng Me 5B | F4: Khắc phục tồn tại công trình ĐTXD Nhánh rẽ Láng Me 5B, C | G4: Từ trụ 120 đến trụ 135 Nhánh rẽ Láng Me 5B | H4: Từ 07 giờ 30 phút – 15 giờ 00 phút. | I4: ="FCO + MCCB TBA "&H4 -> FCO + MCCB TBA Từ 07 giờ 30 phút – 15 giờ 00 phút. | J4: FCO + MCCB | K4: ="Cắt "&I4 -> Cắt FCO + MCCB TBA Từ 07 giờ 30 phút – 15 giờ 00 phút. | L4: ="Tiếp địa hạ thế tại trụ TBA "&H4 -> Tiếp địa hạ thế tại trụ TBA Từ 07 giờ 30 phút – 15 giờ 00 phút. | O4: =K4&CHAR(10)&L4 -> Cắt FCO + MCCB TBA Từ 07 giờ 30 phút – 15 giờ 00 phút. Tiếp địa hạ thế tại trụ TBA Từ 07 giờ 30 phút – 15 giờ 00 phút.
B5: Điện lực Long Khánh | C5: / /2020 | D5: Nguyễn Văn Tây | E5: Lưới điện hạ thế TBA Cây Da 1 | F5: ="Sửa chữa lớn đường dây hạ thế "&E5 -> Sửa chữa lớn đường dây hạ thế Lưới điện hạ thế TBA Cây Da 1 | G5: =E5 -> Lưới điện hạ thế TBA Cây Da 1 | H5: =RIGHT(F5,LEN(F5)-SEARCH("TBA ",F5,1)-2) -> Cây Da 1 | I5: ="FCO + MCCB TBA "&H5 -> FCO + MCCB TBA Cây Da 1 | J5: FCO + MCCB | K5: ="Cắt "&I5 -> Cắt FCO + MCCB TBA Cây Da 1 | L5: ="Tiếp địa hạ thế tại trụ TBA "&H5 -> Tiếp địa hạ thế tại trụ TBA Cây Da 1 | O5: =K5&CHAR(10)&L5 -> Cắt FCO + MCCB TBA Cây Da 1 Tiếp địa hạ thế tại trụ TBA Cây Da 1
C6: / /2020 | D6: Nguyễn Văn Tây | E6: Lưới điện hạ thế TBA Cây Da 2 | F6: ="Sửa chữa lớn đường dây hạ thế "&E6 -> Sửa chữa lớn đường dây hạ thế Lưới điện hạ thế TBA Cây Da 2 | G6: =E6 -> Lưới điện hạ thế TBA Cây Da 2 | H6: =RIGHT(F6,LEN(F6)-SEARCH("TBA ",F6,1)-2) -> Cây Da 2 | I6: ="FCO + MCCB TBA "&H6 -> FCO + MCCB TBA Cây Da 2 | J6: FCO + MCCB | K6: ="Cắt "&I6 -> Cắt FCO + MCCB TBA Cây Da 2 | L6: ="Tiếp địa hạ thế tại trụ TBA "&H6 -> Tiếp địa hạ thế tại trụ TBA Cây Da 2 | O6: =K6&CHAR(10)&L6 -> Cắt FCO + MCCB TBA Cây Da 2 Tiếp địa hạ thế tại trụ TBA Cây Da 2
C7: / /2021 | D7: Nguyễn Văn Tây | E7: Lưới điện hạ thế TBA Cây Da 2A | F7: ="Sửa chữa lớn đường dây hạ thế "&E7 -> Sửa chữa lớn đường dây hạ thế Lưới điện hạ thế TBA Cây Da 2A | G7: =E7 -> Lưới điện hạ thế TBA Cây Da 2A | H7: =RIGHT(F7,LEN(F7)-SEARCH("TBA ",F7,1)-2) -> Cây Da 2A | I7: ="FCO + MCCB TBA "&H7 -> FCO + MCCB TBA Cây Da 2A | J7: FCO + MCCB | K7: ="Cắt "&I7 -> Cắt FCO + MCCB TBA Cây Da 2A | L7: ="Tiếp địa hạ thế tại trụ TBA "&H7 -> Tiếp địa hạ thế tại trụ TBA Cây Da 2A | O7: =K7&CHAR(10)&L7 -> Cắt FCO + MCCB TBA Cây Da 2A Tiếp địa hạ thế tại trụ TBA Cây Da 2A
C8: / /2022 | D8: Nguyễn Văn Tây | E8: Lưới điện hạ thế TBA Cây Da 3 | F8: ="Sửa chữa lớn đường dây hạ thế "&E8 -> Sửa chữa lớn đường dây hạ thế Lưới điện hạ thế TBA Cây Da 3 | G8: =E8 -> Lưới điện hạ thế TBA Cây Da 3 | H8: =RIGHT(F8,LEN(F8)-SEARCH("TBA ",F8,1)-2) -> Cây Da 3 | I8: ="FCO + MCCB TBA "&H8 -> FCO + MCCB TBA Cây Da 3 | J8: FCO + MCCB | K8: ="Cắt "&I8 -> Cắt FCO + MCCB TBA Cây Da 3 | L8: ="Tiếp địa hạ thế tại trụ TBA "&H8 -> Tiếp địa hạ thế tại trụ TBA Cây Da 3 | O8: =K8&CHAR(10)&L8 -> Cắt FCO + MCCB TBA Cây Da 3 Tiếp địa hạ thế tại trụ TBA Cây Da 3
C9: / /2023 | D9: Nguyễn Văn Tây | E9: Lưới điện hạ thế TBA Cây Da 4 | F9: ="Sửa chữa lớn đường dây hạ thế "&E9 -> Sửa chữa lớn đường dây hạ thế Lưới điện hạ thế TBA Cây Da 4 | G9: =E9 -> Lưới điện hạ thế TBA Cây Da 4 | H9: =RIGHT(F9,LEN(F9)-SEARCH("TBA ",F9,1)-2) -> Cây Da 4 | I9: ="FCO + MCCB TBA "&H9 -> FCO + MCCB TBA Cây Da 4 | J9: FCO + MCCB | K9: ="Cắt "&I9 -> Cắt FCO + MCCB TBA Cây Da 4 | L9: ="Tiếp địa hạ thế tại trụ TBA "&H9 -> Tiếp địa hạ thế tại trụ TBA Cây Da 4 | O9: =K9&CHAR(10)&L9 -> Cắt FCO + MCCB TBA Cây Da 4 Tiếp địa hạ thế tại trụ TBA Cây Da 4
C10: / /2024 | D10: Nguyễn Văn Tây | E10: Lưới điện hạ thế TBA Cây Da 5 | F10: ="Sửa chữa lớn đường dây hạ thế "&E10 -> Sửa chữa lớn đường dây hạ thế Lưới điện hạ thế TBA Cây Da 5 | G10: =E10 -> Lưới điện hạ thế TBA Cây Da 5 | H10: =RIGHT(F10,LEN(F10)-SEARCH("TBA ",F10,1)-2) -> Cây Da 5 | I10: ="FCO + MCCB TBA "&H10 -> FCO + MCCB TBA Cây Da 5 | J10: FCO + MCCB | K10: ="Cắt "&I10 -> Cắt FCO + MCCB TBA Cây Da 5 | L10: ="Tiếp địa hạ thế tại trụ TBA "&H10 -> Tiếp địa hạ thế tại trụ TBA Cây Da 5 | O10: =K10&CHAR(10)&L10 -> Cắt FCO + MCCB TBA Cây Da 5 Tiếp địa hạ thế tại trụ TBA Cây Da 5
C11: / /2025 | D11: Nguyễn Văn Tây | E11: Lưới điện hạ thế TBA Cây Da 5A | F11: ="Sửa chữa lớn đường dây hạ thế "&E11 -> Sửa chữa lớn đường dây hạ thế Lưới điện hạ thế TBA Cây Da 5A | G11: =E11 -> Lưới điện hạ thế TBA Cây Da 5A | H11: =RIGHT(F11,LEN(F11)-SEARCH("TBA ",F11,1)-2) -> Cây Da 5A | I11: ="FCO + MCCB TBA "&H11 -> FCO + MCCB TBA Cây Da 5A | J11: FCO + MCCB | K11: ="Cắt "&I11 -> Cắt FCO + MCCB TBA Cây Da 5A | L11: ="Tiếp địa hạ thế tại trụ TBA "&H11 -> Tiếp địa hạ thế tại trụ TBA Cây Da 5A | O11: =K11&CHAR(10)&L11 -> Cắt FCO + MCCB TBA Cây Da 5A Tiếp địa hạ thế tại trụ TBA Cây Da 5A
C12: / /2026 | D12: Nguyễn Văn Tây | E12: Lưới điện hạ thế TBA Cây Da 6 | F12: ="Sửa chữa lớn đường dây hạ thế "&E12 -> Sửa chữa lớn đường dây hạ thế Lưới điện hạ thế TBA Cây Da 6 | G12: =E12 -> Lưới điện hạ thế TBA Cây Da 6 | H12: =RIGHT(F12,LEN(F12)-SEARCH("TBA ",F12,1)-2) -> Cây Da 6 | I12: ="FCO + MCCB TBA "&H12 -> FCO + MCCB TBA Cây Da 6 | J12: FCO + MCCB | K12: ="Cắt "&I12 -> Cắt FCO + MCCB TBA Cây Da 6 | L12: ="Tiếp địa hạ thế tại trụ TBA "&H12 -> Tiếp địa hạ thế tại trụ TBA Cây Da 6 | O12: =K12&CHAR(10)&L12 -> Cắt FCO + MCCB TBA Cây Da 6 Tiếp địa hạ thế tại trụ TBA Cây Da 6
C13: / /2027 | D13: Nguyễn Văn Tây | E13: Lưới điện hạ thế TBA Cây Da 6A | F13: ="Sửa chữa lớn đường dây hạ thế "&E13 -> Sửa chữa lớn đường dây hạ thế Lưới điện hạ thế TBA Cây Da 6A | G13: =E13 -> Lưới điện hạ thế TBA Cây Da 6A | H13: =RIGHT(F13,LEN(F13)-SEARCH("TBA ",F13,1)-2) -> Cây Da 6A | I13: ="FCO + MCCB TBA "&H13 -> FCO + MCCB TBA Cây Da 6A | J13: FCO + MCCB | K13: ="Cắt "&I13 -> Cắt FCO + MCCB TBA Cây Da 6A | L13: ="Tiếp địa hạ thế tại trụ TBA "&H13 -> Tiếp địa hạ thế tại trụ TBA Cây Da 6A | O13: =K13&CHAR(10)&L13 -> Cắt FCO + MCCB TBA Cây Da 6A Tiếp địa hạ thế tại trụ TBA Cây Da 6A | P13: s
C14: / /2028 | D14: Nguyễn Văn Tây | E14: Lưới điện hạ thế TBA Cây Da 7 | F14: ="Sửa chữa lớn đường dây hạ thế "&E14 -> Sửa chữa lớn đường dây hạ thế Lưới điện hạ thế TBA Cây Da 7 | G14: =E14 -> Lưới điện hạ thế TBA Cây Da 7 | H14: =RIGHT(F14,LEN(F14)-SEARCH("TBA ",F14,1)-2) -> Cây Da 7 | I14: ="FCO + MCCB TBA "&H14 -> FCO + MCCB TBA Cây Da 7 | J14: FCO + MCCB | K14: ="Cắt "&I14 -> Cắt FCO + MCCB TBA Cây Da 7 | L14: ="Tiếp địa hạ thế tại trụ TBA "&H14 -> Tiếp địa hạ thế tại trụ TBA Cây Da 7 | O14: =K14&CHAR(10)&L14 -> Cắt FCO + MCCB TBA Cây Da 7 Tiếp địa hạ thế tại trụ TBA Cây Da 7
C15: / /2028 | D15: Nguyễn Văn Tây | E15: Lưới điện hạ thế TBA Cây Da 10 | F15: ="Sửa chữa lớn đường dây hạ thế "&E15 -> Sửa chữa lớn đường dây hạ thế Lưới điện hạ thế TBA Cây Da 10 | G15: =E15 -> Lưới điện hạ thế TBA Cây Da 10 | H15: =RIGHT(F15,LEN(F15)-SEARCH("TBA ",F15,1)-2) -> Cây Da 10 | I15: ="FCO + MCCB TBA "&H15 -> FCO + MCCB TBA Cây Da 10 | J15: FCO + MCCB | K15: ="Cắt "&I15 -> Cắt FCO + MCCB TBA Cây Da 10 | L15: ="Tiếp địa hạ thế tại trụ TBA "&H15 -> Tiếp địa hạ thế tại trụ TBA Cây Da 10 | O15: =K15&CHAR(10)&L15 -> Cắt FCO + MCCB TBA Cây Da 10 Tiếp địa hạ thế tại trụ TBA Cây Da 10
C16: / /2028 | D16: Nguyễn Văn Tây | E16: Lưới điện hạ thế TBA Cây Da 11 | F16: ="Sửa chữa lớn đường dây hạ thế "&E16 -> Sửa chữa lớn đường dây hạ thế Lưới điện hạ thế TBA Cây Da 11 | G16: =E16 -> Lưới điện hạ thế TBA Cây Da 11 | H16: =RIGHT(F16,LEN(F16)-SEARCH("TBA ",F16,1)-2) -> Cây Da 11 | I16: ="FCO + MCCB TBA "&H16 -> FCO + MCCB TBA Cây Da 11 | J16: FCO + MCCB | K16: ="Cắt "&I16 -> Cắt FCO + MCCB TBA Cây Da 11 | L16: ="Tiếp địa hạ thế tại trụ TBA "&H16 -> Tiếp địa hạ thế tại trụ TBA Cây Da 11 | O16: =K16&CHAR(10)&L16 -> Cắt FCO + MCCB TBA Cây Da 11 Tiếp địa hạ thế tại trụ TBA Cây Da 11
C17: 28/10/2020 | D17: Mai Văn Thái | E17: Nhánh rẽ Nhân Nghĩa 11 | F17: Nâng cấp đường dây trung thế nhánh rẽ Nhân Nghĩa 11 từ 1 pha lên 3 pha | G17: Từ trụ 172 đến trụ 172/005 nhánh rẽ Nhân Nghĩa 11 | H17: Từ 07 giờ 30 phút – 11 giờ 00 phút. | I17: Cắt LBS khí + 3 LTD | K17: Cắt LBS khí Ấp 8 Nhân Nghĩa + 3 LTD Cắt LBS khí Nhân Nghĩa - Xuân Bảo + 3LTD Tiếp địa trụ trung thế 174 | L17: Tiếp địa hạ thế tại TBA Nhân Nghĩa 11 | N17: 44147 | O17: =K17&CHAR(10)&L17 -> Cắt LBS khí Ấp 8 Nhân Nghĩa + 3 LTD Cắt LBS khí Nhân Nghĩa - Xuân Bảo + 3LTD Tiếp địa trụ trung thế 174 Tiếp địa hạ thế tại TBA Nhân Nghĩa 11 | P17: =E17 -> Nhánh rẽ Nhân Nghĩa 11
C18: 28/10/2020 | D18: Nguyễn Công Lý | E18: Nhánh rẽ Nhân Nghĩa 11 | F18: Nâng cấp đường dây trung thế nhánh rẽ Nhân Nghĩa 11 từ 1 pha lên 3 pha. Đấu nối trung thế nhánh rẽ Nhân Nghĩa 11A | G18: Từ trụ 172/005 đến trụ 172/011 nhánh rẽ Nhân Nghĩa 11 | H18: Từ 08 giờ 30 phút – 16 giờ 00 phút. | I18: FCO | K18: Cắt FCO nhánh rẽ Nhân Nghĩa 11 tại trụ 172/001 | L18: Tiếp địa trung hạ thế tại TBA Nhân Nghĩa 11 | N18: 44147 | O18: =K18&CHAR(10)&L18 -> Cắt FCO nhánh rẽ Nhân Nghĩa 11 tại trụ 172/001 Tiếp địa trung hạ thế tại TBA Nhân Nghĩa 11 | P18: =E18 -> Nhánh rẽ Nhân Nghĩa 11
A19: =ROW() -> 19 | C19: 44061 | E19: TBA Nam Hà 1A | F19: Thay dây hạ thế sau TBA Nam Hà 1A | G19: Lưới điện hạ thế thuộc trạm Nam Hà 1A | H19: Từ 07 giờ 30 phút – 15 giờ 00 phút. | I19: FCO + MCCB | K19: Cắt FCO + MCCB TBA Nam Hà 1A Tiếp địa hạ thế tại MCCB TBA Nam Hà 1A | N19: =M19+14 -> 14 | O19: {=_xlfn.TEXTJOIN(CHAR(10),TRUE,K19:L19)} -> Cắt FCO + MCCB TBA Nam Hà 1A Tiếp địa hạ thế tại MCCB TBA Nam Hà 1A | P19: =E19 -> TBA Nam Hà 1A | Q19: =O19&E19 -> Cắt FCO + MCCB TBA Nam Hà 1A Tiếp địa hạ thế tại MCCB TBA Nam Hà 1ATBA Nam Hà 1A | R19: 44079 | S19: Công ty TNHH Thu Lộc | T19: =WEEKDAY(R19) -> 7 | U19: =O19&E19 -> Cắt FCO + MCCB TBA Nam Hà 1A Tiếp địa hạ thế tại MCCB TBA Nam Hà 1ATBA Nam Hà 1A | V19: =F19&LOWER(O19)&E19 -> Thay dây hạ thế sau TBA Nam Hà 1Acắt fco + mccb tba nam hà 1a tiếp địa hạ thế tại mccb tba nam hà 1aTBA Nam Hà 1A | W19: ="Cắt "&I19&P19 -> Cắt FCO + MCCB TBA Nam Hà 1A | X19: ="Tiếp địa tại "&L19&E19 -> Tiếp địa tại TBA Nam Hà 1A
A20: =ROW() -> 20 | C20: 44061 | E20: TBA Nam Hà 1 | F20: Thay dây hạ thế sau TBA Nam Hà 1 | G20: Lưới hạ thế thuộc trạm Nam Hà 1 | H20: Từ 07 giờ 30 phút – 15 giờ 00 phút. | I20: FCO + MCCB | K20: Cắt FCO + MCCB TBA Nam Hà 1 Tiếp địa hạ thế tại MCCB TBA Nam Hà 1 | N20: =M20+14 -> 14 | O20: {=_xlfn.TEXTJOIN(CHAR(10),TRUE,K20:L20)} -> Cắt FCO + MCCB TBA Nam Hà 1 Tiếp địa hạ thế tại MCCB TBA Nam Hà 1 | P20: =E20 -> TBA Nam Hà 1 | Q20: =O20&E20 -> Cắt FCO + MCCB TBA Nam Hà 1 Tiếp địa hạ thế tại MCCB TBA Nam Hà 1 TBA Nam Hà 1 | R20: 44079 | S20: Công ty TNHH Thu Lộc | T20: =WEEKDAY(R20) -> 7 | U20: =O20&E20 -> Cắt FCO + MCCB TBA Nam Hà 1 Tiếp địa hạ thế tại MCCB TBA Nam Hà 1 TBA Nam Hà 1 | V20: =F20&LOWER(O20)&E20 -> Thay dây hạ thế sau TBA Nam Hà 1cắt fco + mccb tba nam hà 1 tiếp địa hạ thế tại mccb tba nam hà 1 TBA Nam Hà 1 | W20: ="Cắt "&I20&P20 -> Cắt FCO + MCCB TBA Nam Hà 1 | X20: ="Tiếp địa tại "&L20&E20 -> Tiếp địa tại TBA Nam Hà 1
A21: =ROW() -> 21 | C21: 44061 | E21: TBA Nam Hà 3 | F21: Thay dây hạ thế sau TBA Nam Hà 3 | G21: Lưới điện hạ thế thuộc trạm Nam Hà 3 | H21: Từ 07 giờ 30 phút – 15 giờ 00 phút. | I21: FCO + MCCB | K21: Cắt FCO + MCCB TBA Nam Hà 3 Tiếp địa hạ thế tại MCCB TBA Nam Hà 3 | N21: =M21+14 -> 14 | O21: {=_xlfn.TEXTJOIN(CHAR(10),TRUE,K21:L21)} -> Cắt FCO + MCCB TBA Nam Hà 3 Tiếp địa hạ thế tại MCCB TBA Nam Hà 3 | P21: =E21 -> TBA Nam Hà 3 | Q21: =O21&E21 -> Cắt FCO + MCCB TBA Nam Hà 3 Tiếp địa hạ thế tại MCCB TBA Nam Hà 3TBA Nam Hà 3 | R21: 44079 | S21: Công ty TNHH Thu Lộc | T21: =WEEKDAY(R21) -> 7 | U21: =O21&E21 -> Cắt FCO + MCCB TBA Nam Hà 3 Tiếp địa hạ thế tại MCCB TBA Nam Hà 3TBA Nam Hà 3 | V21: =F21&LOWER(O21)&E21 -> Thay dây hạ thế sau TBA Nam Hà 3cắt fco + mccb tba nam hà 3 tiếp địa hạ thế tại mccb tba nam hà 3TBA Nam Hà 3 | W21: ="Cắt "&I21&P21 -> Cắt FCO + MCCB TBA Nam Hà 3 | X21: ="Tiếp địa tại "&L21&E21 -> Tiếp địa tại TBA Nam Hà 3
A22: =ROW() -> 22 | C22: 44061 | E22: TBA Xuân Tây 10A | F22: Thay dây hạ thế sau TBA Xuân Tây 10A | G22: Đường dây hạ thế thuộc trạm biến áp Xuân Tây 10A | H22: Từ 07 giờ 30 phút – 15 giờ 00 phút. | I22: FCO + MCCB | K22: Cắt FCO + MCCB TBA Xuân Tây 10A Tiếp địa hạ thế tại MCCB TBA Xuân Tây 10A | N22: =M22+14 -> 14 | O22: {=_xlfn.TEXTJOIN(CHAR(10),TRUE,K22:L22)} -> Cắt FCO + MCCB TBA Xuân Tây 10A Tiếp địa hạ thế tại MCCB TBA Xuân Tây 10A | P22: =E22 -> TBA Xuân Tây 10A | Q22: =O22&E22 -> Cắt FCO + MCCB TBA Xuân Tây 10A Tiếp địa hạ thế tại MCCB TBA Xuân Tây 10ATBA Xuân Tây 10A | R22: 44081 | S22: Công ty TNHH Thu Lộc | T22: =WEEKDAY(R22) -> 2 | U22: =O22&E22 -> Cắt FCO + MCCB TBA Xuân Tây 10A Tiếp địa hạ thế tại MCCB TBA Xuân Tây 10ATBA Xuân Tây 10A | V22: =F22&LOWER(O22)&E22 -> Thay dây hạ thế sau TBA Xuân Tây 10Acắt fco + mccb tba xuân tây 10a tiếp địa hạ thế tại mccb tba xuân tây 10aTBA Xuân Tây 10A | W22: ="Cắt "&I22&P22 -> Cắt FCO + MCCB TBA Xuân Tây 10A | X22: ="Tiếp địa tại "&L22&E22 -> Tiếp địa tại TBA Xuân Tây 10A
A23: =ROW() -> 23 | C23: 44061 | E23: TBA Sông Ray 8A | F23: Thay dây hạ thế sau TBA Sông Ray 8A | G23: Đường dây hạ thế thuộc Trạm Sông Ray 8A | H23: Từ 07 giờ 30 phút – 15 giờ 00 phút. | I23: FCO + MCCB | K23: Cắt FCO + MCCB TBA Sông Ray 8A | L23: Tiếp địa hạ thế tại MCCB TBA Sông Ray 8A | N23: =M23+14 -> 14 | O23: {=_xlfn.TEXTJOIN(CHAR(10),TRUE,K23:L23)} -> Cắt FCO + MCCB TBA Sông Ray 8A Tiếp địa hạ thế tại MCCB TBA Sông Ray 8A | P23: =E23 -> TBA Sông Ray 8A | Q23: =O23&E23 -> Cắt FCO + MCCB TBA Sông Ray 8A Tiếp địa hạ thế tại MCCB TBA Sông Ray 8ATBA Sông Ray 8A | R23: 44083 | S23: Công ty TNHH Thu Lộc | T23: =WEEKDAY(R23) -> 4 | U23: =O23&E23 -> Cắt FCO + MCCB TBA Sông Ray 8A Tiếp địa hạ thế tại MCCB TBA Sông Ray 8ATBA Sông Ray 8A | V23: =F23&LOWER(O23)&E23 -> Thay dây hạ thế sau TBA Sông Ray 8Acắt fco + mccb tba sông ray 8a tiếp địa hạ thế tại mccb tba sông ray 8aTBA Sông Ray 8A | W23: ="Cắt "&I23&P23 -> Cắt FCO + MCCB TBA Sông Ray 8A | X23: ="Tiếp địa tại "&L23&E23 -> Tiếp địa tại Tiếp địa hạ thế tại MCCB TBA Sông Ray 8ATBA Sông Ray 8A
A24: =ROW() -> 24 | C24: 44061 | E24: Nhánh rẽ Đồng Tâm 1 | F24: Nâng cấp đường dây hạ thế và TBA Sông Ray 7 từ 1 pha lên 3 pha, cấy TBA Sông Ray 7A | G24: Tại trạm biến áp Sông Ray 7 | H24: Từ 07 giờ 30 phút – 15 giờ 00 phút. | I24: LBS khí + 3 LTD | K24: Cắt LBS khí Đồng Tâm 1 + 3 LTD Đồng Tâm 1 Cắt LBS khí Sông Ray + 3 LTD Sông Ray 1 Tiếp địa trụ trung thế 357 | L24: Tiếp địa trụ trung thế 381 Tiếp địa hạ thế TBA Sông Ray 7 | N24: =M24+14 -> 14 | O24: {=_xlfn.TEXTJOIN(CHAR(10),TRUE,K24:L24)} -> Cắt LBS khí Đồng Tâm 1 + 3 LTD Đồng Tâm 1 Cắt LBS khí Sông Ray + 3 LTD Sông Ray 1 Tiếp địa trụ trung thế 357 Tiếp địa trụ trung thế 381 Tiếp địa hạ thế TBA Sông Ray 7 | P24: =E24 -> Nhánh rẽ Đồng Tâm 1 | Q24: =O24&E24 -> Cắt LBS khí Đồng Tâm 1 + 3 LTD Đồng Tâm 1 Cắt LBS khí Sông Ray + 3 LTD Sông Ray 1 Tiếp địa trụ trung thế 357 Tiếp địa trụ trung thế 381 Tiếp địa hạ thế TBA Sông Ray 7Nhánh rẽ Đồng Tâm 1 | R24: 44086 | S24: Công ty TNHH Thu Lộc | T24: =WEEKDAY(R24) -> 7 | U24: =O24&E24 -> Cắt LBS khí Đồng Tâm 1 + 3 LTD Đồng Tâm 1 Cắt LBS khí Sông Ray + 3 LTD Sông Ray 1 Tiếp địa trụ trung thế 357 Tiếp địa trụ trung thế 381 Tiếp địa hạ thế TBA Sông Ray 7Nhánh rẽ Đồng Tâm 1 | V24: =F24&LOWER(O24)&E24 -> Nâng cấp đường dây hạ thế và TBA Sông Ray 7 từ 1 pha lên 3 pha, cấy TBA Sông Ray 7Acắt lbs khí đồng tâm 1 + 3 ltd đồng tâm 1 cắt lbs khí sông ray + 3 ltd sông ray 1 tiếp địa trụ trung thế 357 tiếp địa trụ trung thế 381 tiếp địa hạ thế tba sông ray 7Nhánh rẽ Đồng Tâm 1 | W24: ="Cắt "&I24&P24 -> Cắt LBS khí + 3 LTDNhánh rẽ Đồng Tâm 1 | X24: ="Tiếp địa tại "&L24&E24 -> Tiếp địa tại Tiếp địa trụ trung thế 381 Tiếp địa hạ thế TBA Sông Ray 7Nhánh rẽ Đồng Tâm 1
